Workbook

Sheet 說明
A1: 美股觀察表 · 架構範本 v2
B3: 資料由 GitHub Actions 自動更新。Raw 分頁為管線寫入區，請勿手改。
A5: v2 改了什麼
B6: Raw_Q 從 32 欄砍到 14 欄。只留下你指定的指標，以及計算這些指標所必需的原始欄位。
B7: 刪掉的是：營益率、FCF、杜邦拆解、ROIC、淨負債、有效稅率、adj_gap、PE 百分位、2年CAGR、
B8: 近4季平均加速度、EPS加速度、年度加速度 —— 這些都是我加的，不是你要的。
B9: 新增：殖利率（需要 Raw_Q 的 dps 欄）。
A11: Raw_Q 的 14 欄，每一欄都有用途
B12: ticker / period / fy / fq / period_end → 鍵值與期別對齊
B13: is_est / est_source → 區分實際與預估，避免預估污染歷史
B14: eps_basis → EPS 口徑標記：street=市場口徑；gaap=四層來源
B15: 全部失敗時的降級，PE/PEG 會失真，須注意
B16: revenue → 營收成長率、毛利率分母
B17: gross_profit → 毛利率分子
B18: eps_diluted_adj → EPS、PE、PEG、EPS成長率
B19: shares_diluted → 反推 ROE 淨利、ROE_Forward 的每股淨值
B20: total_equity → ROE 分母
B21: dps → 殖利率
B22: price_at_end → 歷史 PE、PEG_T、歷史殖利率
A24: 抓不到的東西（誠實說明）
B25: Adjusted 淨利：沒有任何 API 提供。它不是損益表項目，只存在於公司財報的 non-GAAP 對帳附註。
B26: 本表用「逐季 adjusted EPS × 稀釋股數」反推，逐季相乘再加總比用單一股數準，但仍是近似值。
B27: Adjusted EPS 本身拿得到，但不是從損益表，是從「歷史財報實際值」那類端點的 actual EPS。
B28: fy / fq：多數來源不直接提供公司自己的財年標號，要從 period_end 推算。
B29: 歷史的 Forward PE（每一年當時的前瞻本益比）：拿不到，歷史分析師共識一般不留存。
A31: 年 與 季 分在哪裡
B32: 年度層 → 「年度檢視」：每一列＝一個完整財年，由 Raw_Q 的季度資料 rollup 而來。
B33: 季度層 → 「季度檢視」：每一列＝一個財季，另有年 × 季矩陣做季節可比的閱讀。
B34: 橫向層 → 「Dashboard」：每一列＝一檔股票，用來跨標的比較與篩選。
B35: 三層共用同一份 Raw_Q，年度值永遠等於該年四季加總，不會有兩套打架的資料。
A37: 加速度只做在季度層
B38: 季度成長率(QoQ) ＝ 本季營收 ÷ 上一季營收 − 1。
B39: 加速度(pp) ＝ 本季QoQ − 上一季QoQ。字面上就是「這季成長率有沒有比上季快」。
B40: 但這一欄會被季節性主宰：旺季 QoQ 天生高、淡季天生低，每年在同一季重複同樣的震盪。
B41: 同期加速度(pp) ＝ 本季QoQ − 去年同一財季的QoQ。一樣在比季度成長率，但基準換成
B42: 去年同一季，季節性自動抵消。實務上這一欄才有訊號，建議以它為主、加速度當參考。
B43: 年度層刻意不放加速度：一年才一個點，訊號遲鈍到失去意義。
A45: 口徑
B46: EPS / PE / PEG / EPS成長 → Adjusted，與分析師預估和市場定價同口徑。
B47: ROE → 分子用 adjusted EPS 反推的淨利，分母用 GAAP 股東權益（你選的口徑）。
...

Sheet Dashboard
A1: 基本 | E1: 估值 | I1: 殖利率 | K1: 成長 | S1: 毛利率 | W1: ROE | Z1: 預估
A2: Ticker | B2: 公司 | C2: 等級 | D2: 股價 | E2: PE_TTM | F2: PE Forward | G2: PEG_T | H2: PEG_F | I2: 殖利率 | J2: 配息YoY | K2: 營收QoQ | L2: 上季QoQ | M2: 加速度(pp) | N2: 動能判讀 | O2: 同期加速度(pp) | P2: 營收YoY | Q2: EPS_YoY | R2: EPS_TTM_YoY | S2: 毛利率 | T2: 5年平均 | U2: vs5年(bps) | V2: ΔGM_YoY(bps) | W2: ROE_TTM | X2: ROE_5年平均 | Y2: ROE Forward | Z2: 當季EPS預估 | AA2: 預估期別 | AB2: 來源 | AC2: 下次財報
A3: =IF(Calc!$A$2="","",Calc!A$2) -> AAPL | B3: =IF(Calc!$A$2="","",Calc!B$2) -> Apple Inc. | C3: =IF(Calc!$A$2="","",Calc!C$2) -> 0 | D3: =IF(Calc!$A$2="","",Calc!D$2) -> 329.35999 | E3: =IF(Calc!$A$2="","",Calc!J$2) -> 37.770641 | F3: =IF(Calc!$A$2="","",Calc!L$2) -> 34.507766 | G3: =IF(Calc!$A$2="","",Calc!N$2) -> 1.1685846 | H3: =IF(Calc!$A$2="","",Calc!O$2) -> 3.9973204 | I3: =IF(Calc!$A$2="","",Calc!Q$2) -> 0.0031880011 | J3: =IF(Calc!$A$2="","",Calc!R$2) -> 0.03960396 | K3: =IF(Calc!$A$2="","",Calc!T$2) -> -0.015892574 | L3: =IF(Calc!$A$2="","",Calc!U$2) -> -0.22657837 | M3: =IF(Calc!$A$2="","",Calc!V$2) -> 21.068579 | N3: =IF(Calc!$A$2="","",Calc!W$2) -> 衰退但收斂 | O3: =IF(Calc!$A$2="","",Calc!X$2) -> -0.20186874 | P3: =IF(Calc!$A$2="","",Calc!S$2) -> 0.16356502 | Q3: =IF(Calc!$A$2="","",Calc!Y$2) -> 0.2866242 | R3: =IF(Calc!$A$2="","",Calc!I$2) -> 0.323217 | S3: =IF(Calc!$A$2="","",Calc!Z$2) -> 0.48652916 | T3: =IF(Calc!$A$2="","",Calc!AA$2) -> 0.45744556 | U3: =IF(Calc!$A$2="","",Calc!AB$2) -> 290.83593 | V3: =IF(Calc!$A$2="","",Calc!AC$2) -> 356.55013 | W3: =IF(Calc!$A$2="","",Calc!AF$2) -> 1.486954 | X3: =IF(Calc!$A$2="","",Calc!AG$2) -> 1.4327803 | Y3: =IF(Calc!$A$2="","",Calc!AH$2) -> 1.2063557 | Z3: =IF(Calc!$A$2="","",Calc!AI$2) -> 1.97656 | AA3: =IF(Calc!$A$2="","",Calc!AJ$2) -> FY2026Q4E | AB3: =IF(Calc!$A$2="","",Calc!AK$2) -> consensus | AC3: =IF(Calc!$A$2="","",Calc!AM$2) -> 46324
A4: =IF(Calc!$A$3="","",Calc!A$3) -> MSFT | B4: =IF(Calc!$A$3="","",Calc!B$3) -> Microsoft Corporation | C4: =IF(Calc!$A$3="","",Calc!C$3) -> 0 | D4: =IF(Calc!$A$3="","",Calc!D$3) -> 500.84 | E4: =IF(Calc!$A$3="","",Calc!J$3) -> 28.983796 | F4: =IF(Calc!$A$3="","",Calc!L$3) -> 24.350072 | G4: =IF(Calc!$A$3="","",Calc!N$3) -> 1.0860961 | H4: =IF(Calc!$A$3="","",Calc!O$3) -> 1.2552977 | I4: =IF(Calc!$A$3="","",Calc!Q$3) -> 0.0071080585 | J4: =IF(Calc!$A$3="","",Calc!R$3) -> 0.098765432 | K4: =IF(Calc!$A$3="","",Calc!T$3) -> 0.085913182 | L4: =IF(Calc!$A$3="","",Calc!U$3) -> 0.01984669 | M4: =IF(Calc!$A$3="","",Calc!V$3) -> 6.6066492 | N4: =IF(Calc!$A$3="","",Calc!W$3) -> 成長且加速 | O4: =IF(Calc!$A$3="","",Calc!X$3) -> -0.50724601 | P4: =IF(Calc!$A$3="","",Calc!S$3) -> 0.17747021 | Q4: =IF(Calc!$A$3="","",Calc!Y$3) -> 0.29863014 | R4: =IF(Calc!$A$3="","",Calc!I$3) -> 0.26686217 | S4: =IF(Calc!$A$3="","",Calc!Z$3) -> 0.67944093 | T4: =IF(Calc!$A$3="","",Calc!AA$3) -> 0.68725559 | U4: =IF(Calc!$A$3="","",Calc!AB$3) -> -78.146559 | V4: =IF(Calc!$A$3="","",Calc!AC$3) -> -138.79259 | W4: =IF(Calc!$A$3="","",Calc!AF$3) -> 0.32776313 | X4: =IF(Calc!$A$3="","",Calc!AG$3) -> 0.31321768 | Y4: =IF(Calc!$A$3="","",Calc!AH$3) -> 0.33245009 | Z4: =IF(Calc!$A$3="","",Calc!AI$3) -> 4.72092 | AA4: =IF(Calc!$A$3="","",Calc!AJ$3) -> FY2027Q1E | AB4: =IF(Calc!$A$3="","",Calc!AK$3) -> consensus | AC4: =IF(Calc!$A$3="","",Calc!AM$3) -> 46323
A5: =IF(Calc!$A$4="","",Calc!A$4) -> NVDA | B5: =IF(Calc!$A$4="","",Calc!B$4) -> NVIDIA Corporation | C5: =IF(Calc!$A$4="","",Calc!C$4) -> 0 | D5: =IF(Calc!$A$4="","",Calc!D$4) -> 212.27 | E5: =IF(Calc!$A$4="","",Calc!J$4) -> 30.281028 | F5: =IF(Calc!$A$4="","",Calc!L$4) -> 16.044669 | G5: =IF(Calc!$A$4="","",Calc!N$4) -> 0.3124651 | H5: =IF(Calc!$A$4="","",Calc!O$4) -> 0.23672348 | I5: =IF(Calc!$A$4="","",Calc!Q$4) -> 0.0013190747 | J5: =IF(Calc!$A$4="","",Calc!R$4) -> 6 | K5: =IF(Calc!$A$4="","",Calc!T$4) -> 2.7121853 | L5: =IF(Calc!$A$4="","",Calc!U$4) -> 0.19798318 | M5: =IF(Calc!$A$4="","",Calc!V$4) -> 251.42021 | N5: =IF(Calc!$A$4="","",Calc!W$4) -> 成長且加速 | O5: =IF(Calc!$A$4="","",Calc!X$4) -> 265.13392 | P5: =IF(Calc!$A$4="","",Calc!S$4) -> 5.4816122 | Q5: =IF(Calc!$A$4="","",Calc!Y$4) -> 1.1142857 | R5: =IF(Calc!$A$4="","",Calc!I$4) -> 0.96910112 | S5: =IF(Calc!$A$4="","",Calc!Z$4) -> 0.7461773 | T5: =IF(Calc!$A$4="","",Calc!AA$4) -> 0.72932076 | U5: =IF(Calc!$A$4="","",Calc!AB$4) -> 168.56542 | V5: =IF(Calc!$A$4="","",Calc!AC$4) -> 225.07118 | W5: =IF(Calc!$A$4="","",Calc!AF$4) -> 1.0402526 | X5: =IF(Calc!$A$4="","",Calc!AG$4) -> 0.6367055 | Y5: =IF(Calc!$A$4="","",Calc!AH$4) -> 0.99161671 | Z5: =IF(Calc!$A$4="","",Calc!AI$4) -> 2.34 | AA5: =IF(Calc!$A$4="","",Calc!AJ$4) -> FY2027Q3E | AB5: =IF(Calc!$A$4="","",Calc!AK$4) -> consensus | AC5: =IF(Calc!$A$4="","",Calc!AM$4) -> 46343
A6: =IF(Calc!$A$5="","",Calc!A$5) -> AAOI | B6: =IF(Calc!$A$5="","",Calc!B$5) -> Applied Optoelectronics, Inc. | C6: =IF(Calc!$A$5="","",Calc!C$5) -> 觀察 | D6: =IF(Calc!$A$5="","",Calc!D$5) -> 96.349998 | E6: =IF(Calc!$A$5="","",Calc!J$5) -> N/M | F6: =IF(Calc!$A$5="","",Calc!L$5) -> 27.909229 | G6: =IF(Calc!$A$5="","",Calc!N$5) -> N/M | H6: =IF(Calc!$A$5="","",Calc!O$5) -> 0.04838928 | I6: =IF(Calc!$A$5="","",Calc!Q$5) -> 不配息 | J6: =IF(Calc!$A$5="","",Calc!R$5) | K6: =IF(Calc!$A$5="","",Calc!T$5) -> 0.26979569 | L6: =IF(Calc!$A$5="","",Calc!U$5) -> 0.12563862 | M6: =IF(Calc!$A$5="","",Calc!V$5) -> 14.415707 | N6: =IF(Calc!$A$5="","",Calc!W$5) -> 成長且加速 | O6: =IF(Calc!$A$5="","",Calc!X$5) -> 23.882202 | P6: =IF(Calc!$A$5="","",Calc!S$5) -> 0.86418914 | Q6: =IF(Calc!$A$5="","",Calc!Y$5) -> -1.375 | R6: =IF(Calc!$A$5="","",Calc!I$5) -> -0.73170732 | S6: =IF(Calc!$A$5="","",Calc!Z$5) -> 0.28915885 | T6: =IF(Calc!$A$5="","",Calc!AA$5) -> 0.25346476 | U6: =IF(Calc!$A$5="","",Calc!AB$5) -> 356.94087 | V6: =IF(Calc!$A$5="","",Calc!AC$5) -> -254.52329 | W6: =IF(Calc!$A$5="","",Calc!AF$5) -> -0.0065240998 | X6: =IF(Calc!$A$5="","",Calc!AG$5) -> -0.12618364 | Y6: =IF(Calc!$A$5="","",Calc!AH$5) -> 0.033252643 | Z6: =IF(Calc!$A$5="","",Calc!AI$5) -> 0.14333 | AA6: =IF(Calc!$A$5="","",Calc!AJ$5) -> FY2026Q3E | AB6: =IF(Calc!$A$5="","",Calc!AK$5) -> consensus | AC6: =IF(Calc!$A$5="","",Calc!AM$5) -> 46331
A7: =IF(Calc!$A$6="","",Calc!A$6) -> MRVL | B7: =IF(Calc!$A$6="","",Calc!B$6) -> Marvell Technology, Inc. | C7: =IF(Calc!$A$6="","",Calc!C$6) -> 池子 | D7: =IF(Calc!$A$6="","",Calc!D$6) -> 224.32001 | E7: =IF(Calc!$A$6="","",Calc!J$6) -> 67.97576 | F7: =IF(Calc!$A$6="","",Calc!L$6) -> 38.692999 | G7: =IF(Calc!$A$6="","",Calc!N$6) -> 1.6092221 | H7: =IF(Calc!$A$6="","",Calc!O$6) -> 0.63972433 | I7: =IF(Calc!$A$6="","",Calc!Q$6) -> 0.0010699001 | J7: =IF(Calc!$A$6="","",Calc!R$6) -> 0 | K7: =IF(Calc!$A$6="","",Calc!T$6) -> 0.13297212 | L7: =IF(Calc!$A$6="","",Calc!U$6) -> 0.089737234 | M7: =IF(Calc!$A$6="","",Calc!V$6) -> 4.323489 | N7: =IF(Calc!$A$6="","",Calc!W$6) -> 成長且加速 | O7: =IF(Calc!$A$6="","",Calc!X$6) -> 7.4511721 | P7: =IF(Calc!$A$6="","",Calc!S$6) -> 0.36548527 | Q7: =IF(Calc!$A$6="","",Calc!Y$6) -> 0.40298507 | R7: =IF(Calc!$A$6="","",Calc!I$6) -> 0.42241379 | S7: =IF(Calc!$A$6="","",Calc!Z$6) -> 0.52211041 | T7: =IF(Calc!$A$6="","",Calc!AA$6) -> 0.47838083 | U7: =IF(Calc!$A$6="","",Calc!AB$6) -> 437.29583 | V7: =IF(Calc!$A$6="","",Calc!AC$6) -> 276.13108 | W7: =IF(Calc!$A$6="","",Calc!AF$6) -> 0.18288815 | X7: =IF(Calc!$A$6="","",Calc!AG$6) -> 0.098821299 | Y7: =IF(Calc!$A$6="","",Calc!AH$6) -> 0.20941497 | Z7: =IF(Calc!$A$6="","",Calc!AI$6) -> 1.1004 | AA7: =IF(Calc!$A$6="","",Calc!AJ$6) -> FY2027Q3E | AB7: =IF(Calc!$A$6="","",Calc!AK$6) -> consensus | AC7: =IF(Calc!$A$6="","",Calc!AM$6) -> 46357
A8: =IF(Calc!$A$7="","",Calc!A$7) -> MU | B8: =IF(Calc!$A$7="","",Calc!B$7) -> Micron Technology, Inc. | C8: =IF(Calc!$A$7="","",Calc!C$7) -> 池子 | D8: =IF(Calc!$A$7="","",Calc!D$7) -> 932.77002 | E8: =IF(Calc!$A$7="","",Calc!J$7) -> 20.673094 | F8: =IF(Calc!$A$7="","",Calc!L$7) -> 5.9767637 | G8: =IF(Calc!$A$7="","",Calc!N$7) -> 0.034419526 | H8: =IF(Calc!$A$7="","",Calc!O$7) -> 0.053121205 | I8: =IF(Calc!$A$7="","",Calc!Q$7) -> 0.00053067743 | J8: =IF(Calc!$A$7="","",Calc!R$7) -> 0.076086957 | K8: =IF(Calc!$A$7="","",Calc!T$7) -> 0.73746857 | L8: =IF(Calc!$A$7="","",Calc!U$7) -> 0.74888221 | M8: =IF(Calc!$A$7="","",Calc!V$7) -> -1.1413644 | N8: =IF(Calc!$A$7="","",Calc!W$7) -> 成長但減速 | O8: =IF(Calc!$A$7="","",Calc!X$7) -> 58.249526 | P8: =IF(Calc!$A$7="","",Calc!S$7) -> 3.4571551 | Q8: =IF(Calc!$A$7="","",Calc!Y$7) -> 12.146597 | R8: =IF(Calc!$A$7="","",Calc!I$7) -> 6.0062112 | S8: =IF(Calc!$A$7="","",Calc!Z$7) -> 0.72569068 | T8: =IF(Calc!$A$7="","",Calc!AA$7) -> 0.49656668 | U8: =IF(Calc!$A$7="","",Calc!AB$7) -> 2291.24 | V8: =IF(Calc!$A$7="","",Calc!AC$7) -> 4684.5571 | W8: =IF(Calc!$A$7="","",Calc!AF$7) -> 0.68065279 | X8: =IF(Calc!$A$7="","",Calc!AG$7) -> 0.17985176 | Y8: =IF(Calc!$A$7="","",Calc!AH$7) -> 0.83482975 | Z8: =IF(Calc!$A$7="","",Calc!AI$7) -> 31.28341 | AA8: =IF(Calc!$A$7="","",Calc!AJ$7) -> FY2026Q4E | AB8: =IF(Calc!$A$7="","",Calc!AK$7) -> consensus | AC8: =IF(Calc!$A$7="","",Calc!AM$7) -> 46295
A9: =IF(Calc!$A$8="","",Calc!A$8) -> TER | B9: =IF(Calc!$A$8="","",Calc!B$8) -> Teradyne, Inc. | C9: =IF(Calc!$A$8="","",Calc!C$8) -> 池子 | D9: =IF(Calc!$A$8="","",Calc!D$8) -> 328.125 | E9: =IF(Calc!$A$8="","",Calc!J$8) -> 42.724609 | F9: =IF(Calc!$A$8="","",Calc!L$8) -> 30.098632 | G9: =IF(Calc!$A$8="","",Calc!N$8) -> 0.3003038 | H9: =IF(Calc!$A$8="","",Calc!O$8) -> 1.0683958 | I9: =IF(Calc!$A$8="","",Calc!Q$8) -> 0.0015238095 | J9: =IF(Calc!$A$8="","",Calc!R$8) -> 0.041666667 | K9: =IF(Calc!$A$8="","",Calc!T$8) -> 0.036254361 | L9: =IF(Calc!$A$8="","",Calc!U$8) -> 0.18383661 | M9: =IF(Calc!$A$8="","",Calc!V$8) -> -14.758225 | N9: =IF(Calc!$A$8="","",Calc!W$8) -> 成長但減速 | O9: =IF(Calc!$A$8="","",Calc!X$8) -> 8.566954 | P9: =IF(Calc!$A$8="","",Calc!S$8) -> 1.0389631 | Q9: =IF(Calc!$A$8="","",Calc!Y$8) -> 3.3333333 | R9: =IF(Calc!$A$8="","",Calc!I$8) -> 1.4227129 | S9: =IF(Calc!$A$8="","",Calc!Z$8) -> 0.59241591 | T9: =IF(Calc!$A$8="","",Calc!AA$8) -> 0.5883855 | U9: =IF(Calc!$A$8="","",Calc!AB$8) -> 40.304133 | V9: =IF(Calc!$A$8="","",Calc!AC$8) -> 256.28721 | W9: =IF(Calc!$A$8="","",Calc!AF$8) -> 0.38634513 | X9: =IF(Calc!$A$8="","",Calc!AG$8) -> 0.19783528 | Y9: =IF(Calc!$A$8="","",Calc!AH$8) -> 0.41709782 | Z9: =IF(Calc!$A$8="","",Calc!AI$8) -> 2.05052 | AA9: =IF(Calc!$A$8="","",Calc!AJ$8) -> FY2026Q3E | AB9: =IF(Calc!$A$8="","",Calc!AK$8) -> consensus | AC9: =IF(Calc!$A$8="","",Calc!AM$8) -> 46316
A10: =IF(Calc!$A$9="","",Calc!A$9) -> DELL | B10: =IF(Calc!$A$9="","",Calc!B$9) -> Dell Technologies Inc. | C10: =IF(Calc!$A$9="","",Calc!C$9) -> 池子 | D10: =IF(Calc!$A$9="","",Calc!D$9) -> 555.69012 | E10: =IF(Calc!$A$9="","",Calc!J$9) -> 40.680097 | F10: =IF(Calc!$A$9="","",Calc!L$9) -> 22.117062 | G10: =IF(Calc!$A$9="","",Calc!N$9) -> 0.62416401 | H10: =IF(Calc!$A$9="","",Calc!O$9) -> N/M | I10: =IF(Calc!$A$9="","",Calc!Q$9) -> 0.0039680388 | J10: =IF(Calc!$A$9="","",Calc!R$9) -> 0.18548387 | K10: =IF(Calc!$A$9="","",Calc!T$9) -> 0.31346056 | L10: =IF(Calc!$A$9="","",Calc!U$9) -> 0.23603036 | M10: =IF(Calc!$A$9="","",Calc!V$9) -> 7.7430194 | N10: =IF(Calc!$A$9="","",Calc!W$9) -> 成長且加速 | O10: =IF(Calc!$A$9="","",Calc!X$9) -> 33.143922 | P10: =IF(Calc!$A$9="","",Calc!S$9) -> 0.8753529 | Q10: =IF(Calc!$A$9="","",Calc!Y$9) -> 2.1354839 | R10: =IF(Calc!$A$9="","",Calc!I$9) -> 0.65175333 | S10: =IF(Calc!$A$9="","",Calc!Z$9) -> 0.19068372 | T10: =IF(Calc!$A$9="","",Calc!AA$9) -> 0.20559039 | U10: =IF(Calc!$A$9="","",Calc!AB$9) -> -149.06667 | V10: =IF(Calc!$A$9="","",Calc!AC$9) -> -336.80426 | W10: =IF(Calc!$A$9="","",Calc!AF$9) -> N/M | X10: =IF(Calc!$A$9="","",Calc!AG$9) | Y10: =IF(Calc!$A$9="","",Calc!AH$9) -> N/M | Z10: =IF(Calc!$A$9="","",Calc!AI$9) -> 4.91986 | AA10: =IF(Calc!$A$9="","",Calc!AJ$9) -> FY2027Q2E | AB10: =IF(Calc!$A$9="","",Calc!AK$9) -> consensus | AC10: =IF(Calc!$A$9="","",Calc!AM$9) -> 46353
A11: =IF(Calc!$A$10="","",Calc!A$10) -> DIOD | B11: =IF(Calc!$A$10="","",Calc!B$10) -> Diodes Incorporated | C11: =IF(Calc!$A$10="","",Calc!C$10) -> 池子 | D11: =IF(Calc!$A$10="","",Calc!D$10) -> 87.529999 | E11: =IF(Calc!$A$10="","",Calc!J$10) -> 47.570652 | F11: =IF(Calc!$A$10="","",Calc!L$10) -> 17.228689 | G11: =IF(Calc!$A$10="","",Calc!N$10) -> 0.91365854 | H11: =IF(Calc!$A$10="","",Calc!O$10) -> 0.21166675 | I11: =IF(Calc!$A$10="","",Calc!Q$10) -> 不配息 | J11: =IF(Calc!$A$10="","",Calc!R$10) | K11: =IF(Calc!$A$10="","",Calc!T$10) -> 0.098804588 | L11: =IF(Calc!$A$10="","",Calc!U$10) -> 0.035469306 | M11: =IF(Calc!$A$10="","",Calc!V$10) -> 6.3335282 | N11: =IF(Calc!$A$10="","",Calc!W$10) -> 成長且加速 | O11: =IF(Calc!$A$10="","",Calc!X$10) -> -0.38682971 | P11: =IF(Calc!$A$10="","",Calc!S$10) -> 0.21658766 | Q11: =IF(Calc!$A$10="","",Calc!Y$10) -> 1.1875 | R11: =IF(Calc!$A$10="","",Calc!I$10) -> 0.52066116 | S11: =IF(Calc!$A$10="","",Calc!Z$10) -> 0.31734388 | T11: =IF(Calc!$A$10="","",Calc!AA$10) -> 0.36715426 | U11: =IF(Calc!$A$10="","",Calc!AB$10) -> -498.10387 | V11: =IF(Calc!$A$10="","",Calc!AC$10) -> 163.04763 | W11: =IF(Calc!$A$10="","",Calc!AF$10) -> 0.044528376 | X11: =IF(Calc!$A$10="","",Calc!AG$10) -> 0.097373429 | Y11: =IF(Calc!$A$10="","",Calc!AH$10) -> 0.076724004 | Z11: =IF(Calc!$A$10="","",Calc!AI$10) -> 1.055 | AA11: =IF(Calc!$A$10="","",Calc!AJ$10) -> FY2026Q3E | AB11: =IF(Calc!$A$10="","",Calc!AK$10) -> consensus | AC11: =IF(Calc!$A$10="","",Calc!AM$10) -> 46331
A12: =IF(Calc!$A$11="","",Calc!A$11) -> CRWD | B12: =IF(Calc!$A$11="","",Calc!B$11) -> CrowdStrike Holdings, Inc. | C12: =IF(Calc!$A$11="","",Calc!C$11) -> 池子 | D12: =IF(Calc!$A$11="","",Calc!D$11) -> 238.23 | E12: =IF(Calc!$A$11="","",Calc!J$11) -> 214.62162 | F12: =IF(Calc!$A$11="","",Calc!L$11) -> 161.6599 | G12: =IF(Calc!$A$11="","",Calc!N$11) -> 9.1980693 | H12: =IF(Calc!$A$11="","",Calc!O$11) -> 5.8046819 | I12: =IF(Calc!$A$11="","",Calc!Q$11) -> 不配息 | J12: =IF(Calc!$A$11="","",Calc!R$11) | K12: =IF(Calc!$A$11="","",Calc!T$11) -> 2.8943649 | L12: =IF(Calc!$A$11="","",Calc!U$11) -> 0.061479651 | M12: =IF(Calc!$A$11="","",Calc!V$11) -> 283.28853 | N12: =IF(Calc!$A$11="","",Calc!W$11) -> 成長且加速 | O12: =IF(Calc!$A$11="","",Calc!X$11) -> 283.49885 | P12: =IF(Calc!$A$11="","",Calc!S$11) -> 3.6162246 | Q12: =IF(Calc!$A$11="","",Calc!Y$11) -> 0.34782609 | R12: =IF(Calc!$A$11="","",Calc!I$11) -> 0.23333333 | S12: =IF(Calc!$A$11="","",Calc!Z$11) -> 0.75319547 | T12: =IF(Calc!$A$11="","",Calc!AA$11) -> 0.74780075 | U12: =IF(Calc!$A$11="","",Calc!AB$11) -> 53.947188 | V12: =IF(Calc!$A$11="","",Calc!AC$11) -> 173.37196 | W12: =IF(Calc!$A$11="","",Calc!AF$11) -> 0.25655295 | X12: =IF(Calc!$A$11="","",Calc!AG$11) -> 0.1266593 | Y12: =IF(Calc!$A$11="","",Calc!AH$11) -> 0.25186078 | Z12: =IF(Calc!$A$11="","",Calc!AI$11) -> 0.31116 | AA12: =IF(Calc!$A$11="","",Calc!AJ$11) -> FY2027Q3E | AB12: =IF(Calc!$A$11="","",Calc!AK$11) -> consensus | AC12: =IF(Calc!$A$11="","",Calc!AM$11) -> 46357
A13: =IF(Calc!$A$12="","",Calc!A$12) -> NET | B13: =IF(Calc!$A$12="","",Calc!B$12) -> Cloudflare, Inc. | C13: =IF(Calc!$A$12="","",Calc!C$12) -> 核心 | D13: =IF(Calc!$A$12="","",Calc!D$12) -> 327.565 | E13: =IF(Calc!$A$12="","",Calc!J$12) -> 300.51835 | F13: =IF(Calc!$A$12="","",Calc!L$12) -> 210.64263 | G13: =IF(Calc!$A$12="","",Calc!N$12) -> 6.9210287 | H13: =IF(Calc!$A$12="","",Calc!O$12) -> 6.4428141 | I13: =IF(Calc!$A$12="","",Calc!Q$12) -> 不配息 | J13: =IF(Calc!$A$12="","",Calc!R$12) | K13: =IF(Calc!$A$12="","",Calc!T$12) -> 0.088011817 | L13: =IF(Calc!$A$12="","",Calc!U$12) -> 0.041086595 | M13: =IF(Calc!$A$12="","",Calc!V$12) -> 4.6925222 | N13: =IF(Calc!$A$12="","",Calc!W$12) -> 成長且加速 | O13: =IF(Calc!$A$12="","",Calc!X$12) -> 1.8652807 | P13: =IF(Calc!$A$12="","",Calc!S$12) -> 0.3586556 | Q13: =IF(Calc!$A$12="","",Calc!Y$12) -> 0.38095238 | R13: =IF(Calc!$A$12="","",Calc!I$12) -> 0.43421053 | S13: =IF(Calc!$A$12="","",Calc!Z$12) -> 0.72576512 | T13: =IF(Calc!$A$12="","",Calc!AA$12) -> 0.75272195 | U13: =IF(Calc!$A$12="","",Calc!AB$12) -> -269.56831 | V13: =IF(Calc!$A$12="","",Calc!AC$12) -> -311.98809 | W13: =IF(Calc!$A$12="","",Calc!AF$12) -> 0.26822772 | X13: =IF(Calc!$A$12="","",Calc!AG$12) -> 0.18858849 | Y13: =IF(Calc!$A$12="","",Calc!AH$12) -> 0.27628087 | Z13: =IF(Calc!$A$12="","",Calc!AI$12) -> 0.34308 | AA13: =IF(Calc!$A$12="","",Calc!AJ$12) -> FY2026Q3E | AB13: =IF(Calc!$A$12="","",Calc!AK$12) -> consensus | AC13: =IF(Calc!$A$12="","",Calc!AM$12) -> 46324
A14: =IF(Calc!$A$13="","",Calc!A$13) -> CEG | B14: =IF(Calc!$A$13="","",Calc!B$13) -> Constellation Energy Corporation | C14: =IF(Calc!$A$13="","",Calc!C$13) -> 池子 | D14: =IF(Calc!$A$13="","",Calc!D$13) -> 261.25 | E14: =IF(Calc!$A$13="","",Calc!J$13) -> 24.57667 | F14: =IF(Calc!$A$13="","",Calc!L$13) -> 20.122671 | G14: =IF(Calc!$A$13="","",Calc!N$13) -> 1.6203047 | H14: =IF(Calc!$A$13="","",Calc!O$13) -> 1.9923677 | I14: =IF(Calc!$A$13="","",Calc!Q$13) -> 0.0062392344 | J14: =IF(Calc!$A$13="","",Calc!R$13) -> 0.099865047 | K14: =IF(Calc!$A$13="","",Calc!T$13) -> -0.3253012 | L14: =IF(Calc!$A$13="","",Calc!U$13) -> 0.83108331 | M14: =IF(Calc!$A$13="","",Calc!V$13) -> -115.63845 | N14: =IF(Calc!$A$13="","",Calc!W$13) -> 衰退且惡化 | O14: =IF(Calc!$A$13="","",Calc!X$13) -> -22.409319 | P14: =IF(Calc!$A$13="","",Calc!S$13) -> 0.2299623 | Q14: =IF(Calc!$A$13="","",Calc!Y$13) -> 0.33507853 | R14: =IF(Calc!$A$13="","",Calc!I$13) -> 0.15167931 | S14: =IF(Calc!$A$13="","",Calc!Z$13) -> 0.21426287 | T14: =IF(Calc!$A$13="","",Calc!AA$13) -> 0.17324422 | U14: =IF(Calc!$A$13="","",Calc!AB$13) -> 410.18656 | V14: =IF(Calc!$A$13="","",Calc!AC$13) -> -579.5696 | W14: =IF(Calc!$A$13="","",Calc!AF$13) -> 0.15672148 | X14: =IF(Calc!$A$13="","",Calc!AG$13) -> 0.1437463 | Y14: =IF(Calc!$A$13="","",Calc!AH$13) -> 0.13642297 | Z14: =IF(Calc!$A$13="","",Calc!AI$13) -> 3.74379 | AA14: =IF(Calc!$A$13="","",Calc!AJ$13) -> FY2026Q3E | AB14: =IF(Calc!$A$13="","",Calc!AK$13) -> consensus | AC14: =IF(Calc!$A$13="","",Calc!AM$13) -> 46335
A15: =IF(Calc!$A$14="","",Calc!A$14) -> AMZN | B15: =IF(Calc!$A$14="","",Calc!B$14) -> Amazon.com, Inc. | C15: =IF(Calc!$A$14="","",Calc!C$14) -> 池子 | D15: =IF(Calc!$A$14="","",Calc!D$14) -> 248.92999 | E15: =IF(Calc!$A$14="","",Calc!J$14) -> 20.026548 | F15: =IF(Calc!$A$14="","",Calc!L$14) -> 22.233959 | G15: =IF(Calc!$A$14="","",Calc!N$14) -> 0.22380606 | H15: =IF(Calc!$A$14="","",Calc!O$14) -> N/M | I15: =IF(Calc!$A$14="","",Calc!Q$14) -> 不配息 | J15: =IF(Calc!$A$14="","",Calc!R$14) | K15: =IF(Calc!$A$14="","",Calc!T$14) -> 3.2732717 | L15: =IF(Calc!$A$14="","",Calc!U$14) -> -0.14933969 | M15: =IF(Calc!$A$14="","",Calc!V$14) -> 342.26114 | N15: =IF(Calc!$A$14="","",Calc!W$14) -> 成長且加速 | O15: =IF(Calc!$A$14="","",Calc!X$14) -> 319.59592 | P15: =IF(Calc!$A$14="","",Calc!S$14) -> 3.6253473 | Q15: =IF(Calc!$A$14="","",Calc!Y$14) -> 2.422619 | R15: =IF(Calc!$A$14="","",Calc!I$14) -> 0.89481707 | S15: =IF(Calc!$A$14="","",Calc!Z$14) -> 0.50548953 | T15: =IF(Calc!$A$14="","",Calc!AA$14) -> 0.48168494 | U15: =IF(Calc!$A$14="","",Calc!AB$14) -> 238.04584 | V15: =IF(Calc!$A$14="","",Calc!AC$14) -> -104.42846 | W15: =IF(Calc!$A$14="","",Calc!AF$14) -> 0.30551916 | X15: =IF(Calc!$A$14="","",Calc!AG$14) -> 0.16680834 | Y15: =IF(Calc!$A$14="","",Calc!AH$14) -> 0.25485629 | Z15: =IF(Calc!$A$14="","",Calc!AI$14) -> 1.95485 | AA15: =IF(Calc!$A$14="","",Calc!AJ$14) -> FY2026Q3E | AB15: =IF(Calc!$A$14="","",Calc!AK$14) -> consensus | AC15: =IF(Calc!$A$14="","",Calc!AM$14) -> 46324
A16: =IF(Calc!$A$15="","",Calc!A$15) -> GOOG | B16: =IF(Calc!$A$15="","",Calc!B$15) -> Alphabet Inc. | C16: =IF(Calc!$A$15="","",Calc!C$15) -> 池子 | D16: =IF(Calc!$A$15="","",Calc!D$15) -> 340.73999 | E16: =IF(Calc!$A$15="","",Calc!J$15) -> 17.114013 | F16: =IF(Calc!$A$15="","",Calc!L$15) -> 20.598814 | G16: =IF(Calc!$A$15="","",Calc!N$15) -> 0.1527572 | H16: =IF(Calc!$A$15="","",Calc!O$15) -> N/M | I16: =IF(Calc!$A$15="","",Calc!Q$15) -> 0.0024945707 | J16: =IF(Calc!$A$15="","",Calc!R$15) -> 0.049382716 | K16: =IF(Calc!$A$15="","",Calc!T$15) -> 0.090085171 | L16: =IF(Calc!$A$15="","",Calc!U$15) -> -0.034551828 | M16: =IF(Calc!$A$15="","",Calc!V$15) -> 12.4637 | N16: =IF(Calc!$A$15="","",Calc!W$15) -> 成長且加速 | O16: =IF(Calc!$A$15="","",Calc!X$15) -> 2.1441423 | P16: =IF(Calc!$A$15="","",Calc!S$15) -> 0.24233625 | Q16: =IF(Calc!$A$15="","",Calc!Y$15) -> 2.9437229 | R16: =IF(Calc!$A$15="","",Calc!I$15) -> 1.1203408 | S16: =IF(Calc!$A$15="","",Calc!Z$15) -> 0.60896411 | T16: =IF(Calc!$A$15="","",Calc!AA$15) -> 0.52588576 | U16: =IF(Calc!$A$15="","",Calc!AB$15) -> 830.78349 | V16: =IF(Calc!$A$15="","",Calc!AC$15) -> 213.40987 | W16: =IF(Calc!$A$15="","",Calc!AF$15) -> 0.48670064 | X16: =IF(Calc!$A$15="","",Calc!AG$15) -> 0.19374921 | Y16: =IF(Calc!$A$15="","",Calc!AH$15) -> 0.39598319 | Z16: =IF(Calc!$A$15="","",Calc!AI$15) -> 3.00444 | AA16: =IF(Calc!$A$15="","",Calc!AJ$15) -> FY2026Q3E | AB16: =IF(Calc!$A$15="","",Calc!AK$15) -> consensus | AC16: =IF(Calc!$A$15="","",Calc!AM$15) -> 46323
A17: =IF(Calc!$A$16="","",Calc!A$16) -> OKTA | B17: =IF(Calc!$A$16="","",Calc!B$16) -> Okta, Inc. | C17: =IF(Calc!$A$16="","",Calc!C$16) -> 池子 | D17: =IF(Calc!$A$16="","",Calc!D$16) -> 187.755 | E17: =IF(Calc!$A$16="","",Calc!J$16) -> 51.020382 | F17: =IF(Calc!$A$16="","",Calc!L$16) -> 44.612904 | G17: =IF(Calc!$A$16="","",Calc!N$16) -> 3.5714267 | H17: =IF(Calc!$A$16="","",Calc!O$16) -> 3.8996119 | I17: =IF(Calc!$A$16="","",Calc!Q$16) -> 不配息 | J17: =IF(Calc!$A$16="","",Calc!R$16) | K17: =IF(Calc!$A$16="","",Calc!T$16) -> 0.052287582 | L17: =IF(Calc!$A$16="","",Calc!U$16) -> 0.0052562418 | M17: =IF(Calc!$A$16="","",Calc!V$16) -> 4.703134 | N17: =IF(Calc!$A$16="","",Calc!W$16) -> 成長且加速 | O17: =IF(Calc!$A$16="","",Calc!X$16) -> -0.58519532 | P17: =IF(Calc!$A$16="","",Calc!S$16) -> 0.10576923 | Q17: =IF(Calc!$A$16="","",Calc!Y$16) -> 0.15384615 | R17: =IF(Calc!$A$16="","",Calc!I$16) -> 0.14285714 | S17: =IF(Calc!$A$16="","",Calc!Z$16) -> 0.78132118 | T17: =IF(Calc!$A$16="","",Calc!AA$16) -> 0.75164009 | U17: =IF(Calc!$A$16="","",Calc!AB$16) -> 296.81091 | V17: =IF(Calc!$A$16="","",Calc!AC$16) -> 270.42523 | W17: =IF(Calc!$A$16="","",Calc!AF$16) -> 0.095891182 | X17: =IF(Calc!$A$16="","",Calc!AG$16) -> 0.051171527 | Y17: =IF(Calc!$A$16="","",Calc!AH$16) -> 0.10075073 | Z17: =IF(Calc!$A$16="","",Calc!AI$16) -> 0.93474 | AA17: =IF(Calc!$A$16="","",Calc!AJ$16) -> FY2027Q3E | AB17: =IF(Calc!$A$16="","",Calc!AK$16) -> consensus | AC17: =IF(Calc!$A$16="","",Calc!AM$16) -> 46357
A18: =IF(Calc!$A$17="","",Calc!A$17) -> PLTR | B18: =IF(Calc!$A$17="","",Calc!B$17) -> Palantir Technologies Inc. | C18: =IF(Calc!$A$17="","",Calc!C$17) -> 池子 | D18: =IF(Calc!$A$17="","",Calc!D$17) -> 171.81 | E18: =IF(Calc!$A$17="","",Calc!J$17) -> 143.175 | F18: =IF(Calc!$A$17="","",Calc!L$17) -> 81.303137 | G18: =IF(Calc!$A$17="","",Calc!N$17) -> 1.1325783 | H18: =IF(Calc!$A$17="","",Calc!O$17) -> 1.826131 | I18: =IF(Calc!$A$17="","",Calc!Q$17) -> 不配息 | J18: =IF(Calc!$A$17="","",Calc!R$17) | K18: =IF(Calc!$A$17="","",Calc!T$17) -> 0.18552257 | L18: =IF(Calc!$A$17="","",Calc!U$17) -> 0.16049238 | M18: =IF(Calc!$A$17="","",Calc!V$17) -> 2.5030195 | N18: =IF(Calc!$A$17="","",Calc!W$17) -> 成長且加速 | O18: =IF(Calc!$A$17="","",Calc!X$17) -> 4.993246 | P18: =IF(Calc!$A$17="","",Calc!S$17) -> 0.92833495 | Q18: =IF(Calc!$A$17="","",Calc!Y$17) -> 1.5625 | R18: =IF(Calc!$A$17="","",Calc!I$17) -> 1.2641509 | S18: =IF(Calc!$A$17="","",Calc!Z$17) -> 0.84796134 | T18: =IF(Calc!$A$17="","",Calc!AA$17) -> 0.81835015 | U18: =IF(Calc!$A$17="","",Calc!AB$17) -> 296.11195 | V18: =IF(Calc!$A$17="","",Calc!AC$17) -> 388.38942 | W18: =IF(Calc!$A$17="","",Calc!AF$17) -> 0.39279884 | X18: =IF(Calc!$A$17="","",Calc!AG$17) -> 0.20112594 | Y18: =IF(Calc!$A$17="","",Calc!AH$17) -> 0.4224201 | Z18: =IF(Calc!$A$17="","",Calc!AI$17) -> 0.41452 | AA18: =IF(Calc!$A$17="","",Calc!AJ$17) -> FY2026Q3E | AB18: =IF(Calc!$A$17="","",Calc!AK$17) -> consensus | AC18: =IF(Calc!$A$17="","",Calc!AM$17) -> 46328
A19: =IF(Calc!$A$18="","",Calc!A$18) -> SMTC | B19: =IF(Calc!$A$18="","",Calc!B$18) -> Semtech Corporation | C19: =IF(Calc!$A$18="","",Calc!C$18) -> 池子 | D19: =IF(Calc!$A$18="","",Calc!D$18) -> 151.03999 | E19: =IF(Calc!$A$18="","",Calc!J$18) -> 70.579436 | F19: =IF(Calc!$A$18="","",Calc!L$18) -> 30.557512 | G19: =IF(Calc!$A$18="","",Calc!N$18) -> 1.483191 | H19: =IF(Calc!$A$18="","",Calc!O$18) -> 0.44958063 | I19: =IF(Calc!$A$18="","",Calc!Q$18) -> 不配息 | J19: =IF(Calc!$A$18="","",Calc!R$18) | K19: =IF(Calc!$A$18="","",Calc!T$18) -> 0.17474177 | L19: =IF(Calc!$A$18="","",Calc!U$18) -> 0.060735179 | M19: =IF(Calc!$A$18="","",Calc!V$18) -> 11.400659 | N19: =IF(Calc!$A$18="","",Calc!W$18) -> 成長且加速 | O19: =IF(Calc!$A$18="","",Calc!X$18) -> 14.873603 | P19: =IF(Calc!$A$18="","",Calc!S$18) -> 0.32719565 | Q19: =IF(Calc!$A$18="","",Calc!Y$18) -> 0.73170732 | R19: =IF(Calc!$A$18="","",Calc!I$18) -> 0.47586207 | S19: =IF(Calc!$A$18="","",Calc!Z$18) -> 0.52118053 | T19: =IF(Calc!$A$18="","",Calc!AA$18) -> 0.52869047 | U19: =IF(Calc!$A$18="","",Calc!AB$18) -> -75.099376 | V19: =IF(Calc!$A$18="","",Calc!AC$18) -> 169.08212 | W19: =IF(Calc!$A$18="","",Calc!AF$18) -> 0.31401698 | X19: =IF(Calc!$A$18="","",Calc!AG$18) -> 0.20199964 | Y19: =IF(Calc!$A$18="","",Calc!AH$18) -> 0.4676385 | Z19: =IF(Calc!$A$18="","",Calc!AI$18) -> 1.0557 | AA19: =IF(Calc!$A$18="","",Calc!AJ$18) -> FY2027Q3E | AB19: =IF(Calc!$A$18="","",Calc!AK$18) -> consensus | AC19: =IF(Calc!$A$18="","",Calc!AM$18) -> 46349
A20: =IF(Calc!$A$19="","",Calc!A$19) -> QCOM | B20: =IF(Calc!$A$19="","",Calc!B$19) -> QUALCOMM Incorporated | C20: =IF(Calc!$A$19="","",Calc!C$19) -> 池子 | D20: =IF(Calc!$A$19="","",Calc!D$19) -> 187.16251 | E20: =IF(Calc!$A$19="","",Calc!J$19) -> 16.475573 | F20: =IF(Calc!$A$19="","",Calc!L$19) -> 18.321378 | G20: =IF(Calc!$A$19="","",Calc!N$19) -> N/M | H20: =IF(Calc!$A$19="","",Calc!O$19) -> N/M | I20: =IF(Calc!$A$19="","",Calc!Q$19) -> 0.019181192 | J20: =IF(Calc!$A$19="","",Calc!R$19) -> 0.043604651 | K20: =IF(Calc!$A$19="","",Calc!T$19) -> -0.061515237 | L20: =IF(Calc!$A$19="","",Calc!U$19) -> -0.13491675 | M20: =IF(Calc!$A$19="","",Calc!V$19) -> 7.3401511 | N20: =IF(Calc!$A$19="","",Calc!W$19) -> 衰退但收斂 | O20: =IF(Calc!$A$19="","",Calc!X$19) -> -0.55902897 | P20: =IF(Calc!$A$19="","",Calc!S$19) -> -0.040328027 | Q20: =IF(Calc!$A$19="","",Calc!Y$19) -> -0.20216606 | R20: =IF(Calc!$A$19="","",Calc!I$19) -> -0.030716724 | S20: =IF(Calc!$A$19="","",Calc!Z$19) -> 0.54226327 | T20: =IF(Calc!$A$19="","",Calc!AA$19) -> 0.50886811 | U20: =IF(Calc!$A$19="","",Calc!AB$19) -> 333.95163 | V20: =IF(Calc!$A$19="","",Calc!AC$19) -> -251.08163 | W20: =IF(Calc!$A$19="","",Calc!AF$19) -> 0.44521443 | X20: =IF(Calc!$A$19="","",Calc!AG$19) -> 0.46903097 | Y20: =IF(Calc!$A$19="","",Calc!AH$19) -> 0.40522204 | Z20: =IF(Calc!$A$19="","",Calc!AI$19) -> 2.1566 | AA20: =IF(Calc!$A$19="","",Calc!AJ$19) -> FY2026Q4E | AB20: =IF(Calc!$A$19="","",Calc!AK$19) -> consensus | AC20: =IF(Calc!$A$19="","",Calc!AM$19) -> 46324
A21: =IF(Calc!$A$20="","",Calc!A$20) -> AVGO | B21: =IF(Calc!$A$20="","",Calc!B$20) -> Broadcom Inc. | C21: =IF(Calc!$A$20="","",Calc!C$20) -> 池子 | D21: =IF(Calc!$A$20="","",Calc!D$20) -> 341.70001 | E21: =IF(Calc!$A$20="","",Calc!J$20) -> 53.059008 | F21: =IF(Calc!$A$20="","",Calc!L$20) -> 18.560373 | G21: =IF(Calc!$A$20="","",Calc!N$20) -> N/M | H21: =IF(Calc!$A$20="","",Calc!O$20) -> 0.28004597 | I21: =IF(Calc!$A$20="","",Calc!Q$20) -> 0.0074334209 | J21: =IF(Calc!$A$20="","",Calc!R$20) -> 0.10434783 | K21: =IF(Calc!$A$20="","",Calc!T$20) -> 0.33370893 | L21: =IF(Calc!$A$20="","",Calc!U$20) -> 0.14893066 | M21: =IF(Calc!$A$20="","",Calc!V$20) -> 18.477827 | N21: =IF(Calc!$A$20="","",Calc!W$20) -> 成長且加速 | O21: =IF(Calc!$A$20="","",Calc!X$20) -> 27.052578 | P21: =IF(Calc!$A$20="","",Calc!S$20) -> 0.85500251 | Q21: =IF(Calc!$A$20="","",Calc!Y$20) -> -1 | R21: =IF(Calc!$A$20="","",Calc!I$20) -> 0.023847377 | S21: =IF(Calc!$A$20="","",Calc!Z$20) -> 0.68770201 | T21: =IF(Calc!$A$20="","",Calc!AA$20) -> 0.67022082 | U21: =IF(Calc!$A$20="","",Calc!AB$20) -> 174.81195 | V21: =IF(Calc!$A$20="","",Calc!AC$20) -> 203.4092 | W21: =IF(Calc!$A$20="","",Calc!AF$20) -> 0.36366925 | X21: =IF(Calc!$A$20="","",Calc!AG$20) -> 0.25385739 | Y21: =IF(Calc!$A$20="","",Calc!AH$20) -> 0.57148144 | Z21: =IF(Calc!$A$20="","",Calc!AI$20) -> 3.82578 | AA21: =IF(Calc!$A$20="","",Calc!AJ$20) -> FY2026Q4E | AB21: =IF(Calc!$A$20="","",Calc!AK$20) -> consensus | AC21: =IF(Calc!$A$20="","",Calc!AM$20) -> 46365
A22: =IF(Calc!$A$21="","",Calc!A$21) -> FTNT | B22: =IF(Calc!$A$21="","",Calc!B$21) -> Fortinet, Inc. | C22: =IF(Calc!$A$21="","",Calc!C$21) -> 池子 | D22: =IF(Calc!$A$21="","",Calc!D$21) -> 170.17999 | E22: =IF(Calc!$A$21="","",Calc!J$21) -> 52.042811 | F22: =IF(Calc!$A$21="","",Calc!L$21) -> 46.223117 | G22: =IF(Calc!$A$21="","",Calc!N$21) -> 1.9822188 | H22: =IF(Calc!$A$21="","",Calc!O$21) -> 4.866595 | I22: =IF(Calc!$A$21="","",Calc!Q$21) -> 不配息 | J22: =IF(Calc!$A$21="","",Calc!R$21) | K22: =IF(Calc!$A$21="","",Calc!T$21) -> 0.10721237 | L22: =IF(Calc!$A$21="","",Calc!U$21) -> -0.029081365 | M22: =IF(Calc!$A$21="","",Calc!V$21) -> 13.629374 | N22: =IF(Calc!$A$21="","",Calc!W$21) -> 成長且加速 | O22: =IF(Calc!$A$21="","",Calc!X$21) -> 4.8564582 | P22: =IF(Calc!$A$21="","",Calc!S$21) -> 0.25638037 | Q22: =IF(Calc!$A$21="","",Calc!Y$21) -> 0.40625 | R22: =IF(Calc!$A$21="","",Calc!I$21) -> 0.26254826 | S22: =IF(Calc!$A$21="","",Calc!Z$21) -> 0.8020432 | T22: =IF(Calc!$A$21="","",Calc!AA$21) -> 0.7866652 | U22: =IF(Calc!$A$21="","",Calc!AB$21) -> 153.78001 | V22: =IF(Calc!$A$21="","",Calc!AC$21) -> -44.268871 | W22: =IF(Calc!$A$21="","",Calc!AF$21) -> 1.3535506 | X22: =IF(Calc!$A$21="","",Calc!AG$21) -> 2.2266055 | Y22: =IF(Calc!$A$21="","",Calc!AH$21) -> 1.6457444 | Z22: =IF(Calc!$A$21="","",Calc!AI$21) -> 0.85724 | AA22: =IF(Calc!$A$21="","",Calc!AJ$21) -> FY2026Q3E | AB22: =IF(Calc!$A$21="","",Calc!AK$21) -> consensus | AC22: =IF(Calc!$A$21="","",Calc!AM$21) -> 46330
A23: =IF(Calc!$A$22="","",Calc!A$22) | B23: =IF(Calc!$A$22="","",Calc!B$22) | C23: =IF(Calc!$A$22="","",Calc!C$22) | D23: =IF(Calc!$A$22="","",Calc!D$22) | E23: =IF(Calc!$A$22="","",Calc!J$22) | F23: =IF(Calc!$A$22="","",Calc!L$22) | G23: =IF(Calc!$A$22="","",Calc!N$22) | H23: =IF(Calc!$A$22="","",Calc!O$22) | I23: =IF(Calc!$A$22="","",Calc!Q$22) | J23: =IF(Calc!$A$22="","",Calc!R$22) | K23: =IF(Calc!$A$22="","",Calc!T$22) | L23: =IF(Calc!$A$22="","",Calc!U$22) | M23: =IF(Calc!$A$22="","",Calc!V$22) | N23: =IF(Calc!$A$22="","",Calc!W$22) | O23: =IF(Calc!$A$22="","",Calc!X$22) | P23: =IF(Calc!$A$22="","",Calc!S$22) | Q23: =IF(Calc!$A$22="","",Calc!Y$22) | R23: =IF(Calc!$A$22="","",Calc!I$22) | S23: =IF(Calc!$A$22="","",Calc!Z$22) | T23: =IF(Calc!$A$22="","",Calc!AA$22) | U23: =IF(Calc!$A$22="","",Calc!AB$22) | V23: =IF(Calc!$A$22="","",Calc!AC$22) | W23: =IF(Calc!$A$22="","",Calc!AF$22) | X23: =IF(Calc!$A$22="","",Calc!AG$22) | Y23: =IF(Calc!$A$22="","",Calc!AH$22) | Z23: =IF(Calc!$A$22="","",Calc!AI$22) | AA23: =IF(Calc!$A$22="","",Calc!AJ$22) | AB23: =IF(Calc!$A$22="","",Calc!AK$22) | AC23: =IF(Calc!$A$22="","",Calc!AM$22)
A24: =IF(Calc!$A$23="","",Calc!A$23) | B24: =IF(Calc!$A$23="","",Calc!B$23) | C24: =IF(Calc!$A$23="","",Calc!C$23) | D24: =IF(Calc!$A$23="","",Calc!D$23) | E24: =IF(Calc!$A$23="","",Calc!J$23) | F24: =IF(Calc!$A$23="","",Calc!L$23) | G24: =IF(Calc!$A$23="","",Calc!N$23) | H24: =IF(Calc!$A$23="","",Calc!O$23) | I24: =IF(Calc!$A$23="","",Calc!Q$23) | J24: =IF(Calc!$A$23="","",Calc!R$23) | K24: =IF(Calc!$A$23="","",Calc!T$23) | L24: =IF(Calc!$A$23="","",Calc!U$23) | M24: =IF(Calc!$A$23="","",Calc!V$23) | N24: =IF(Calc!$A$23="","",Calc!W$23) | O24: =IF(Calc!$A$23="","",Calc!X$23) | P24: =IF(Calc!$A$23="","",Calc!S$23) | Q24: =IF(Calc!$A$23="","",Calc!Y$23) | R24: =IF(Calc!$A$23="","",Calc!I$23) | S24: =IF(Calc!$A$23="","",Calc!Z$23) | T24: =IF(Calc!$A$23="","",Calc!AA$23) | U24: =IF(Calc!$A$23="","",Calc!AB$23) | V24: =IF(Calc!$A$23="","",Calc!AC$23) | W24: =IF(Calc!$A$23="","",Calc!AF$23) | X24: =IF(Calc!$A$23="","",Calc!AG$23) | Y24: =IF(Calc!$A$23="","",Calc!AH$23) | Z24: =IF(Calc!$A$23="","",Calc!AI$23) | AA24: =IF(Calc!$A$23="","",Calc!AJ$23) | AB24: =IF(Calc!$A$23="","",Calc!AK$23) | AC24: =IF(Calc!$A$23="","",Calc!AM$23)
A25: =IF(Calc!$A$24="","",Calc!A$24) -> ↑ 藍字＝手動輸入。新增股票就在第 2~21 列往下打一列，其餘分頁全自動延伸。 | B25: =IF(Calc!$A$24="","",Calc!B$24) | C25: =IF(Calc!$A$24="","",Calc!C$24) | D25: =IF(Calc!$A$24="","",Calc!D$24) | E25: =IF(Calc!$A$24="","",Calc!J$24) -> N/M | F25: =IF(Calc!$A$24="","",Calc!L$24) -> N/M | G25: =IF(Calc!$A$24="","",Calc!N$24) -> N/M | H25: =IF(Calc!$A$24="","",Calc!O$24) -> N/M | I25: =IF(Calc!$A$24="","",Calc!Q$24) -> 不配息 | J25: =IF(Calc!$A$24="","",Calc!R$24) | K25: =IF(Calc!$A$24="","",Calc!T$24) | L25: =IF(Calc!$A$24="","",Calc!U$24) | M25: =IF(Calc!$A$24="","",Calc!V$24) | N25: =IF(Calc!$A$24="","",Calc!W$24) | O25: =IF(Calc!$A$24="","",Calc!X$24) | P25: =IF(Calc!$A$24="","",Calc!S$24) | Q25: =IF(Calc!$A$24="","",Calc!Y$24) | R25: =IF(Calc!$A$24="","",Calc!I$24) | S25: =IF(Calc!$A$24="","",Calc!Z$24) | T25: =IF(Calc!$A$24="","",Calc!AA$24) | U25: =IF(Calc!$A$24="","",Calc!AB$24) | V25: =IF(Calc!$A$24="","",Calc!AC$24) | W25: =IF(Calc!$A$24="","",Calc!AF$24) -> N/M | X25: =IF(Calc!$A$24="","",Calc!AG$24) | Y25: =IF(Calc!$A$24="","",Calc!AH$24) -> N/M | Z25: =IF(Calc!$A$24="","",Calc!AI$24) -> 0 | AA25: =IF(Calc!$A$24="","",Calc!AJ$24) | AB25: =IF(Calc!$A$24="","",Calc!AK$24) | AC25: =IF(Calc!$A$24="","",Calc!AM$24)
A26: =IF(Calc!$A$25="","",Calc!A$25) | B26: =IF(Calc!$A$25="","",Calc!B$25) | C26: =IF(Calc!$A$25="","",Calc!C$25) | D26: =IF(Calc!$A$25="","",Calc!D$25) | E26: =IF(Calc!$A$25="","",Calc!J$25) | F26: =IF(Calc!$A$25="","",Calc!L$25) | G26: =IF(Calc!$A$25="","",Calc!N$25) | H26: =IF(Calc!$A$25="","",Calc!O$25) | I26: =IF(Calc!$A$25="","",Calc!Q$25) | J26: =IF(Calc!$A$25="","",Calc!R$25) | K26: =IF(Calc!$A$25="","",Calc!T$25) | L26: =IF(Calc!$A$25="","",Calc!U$25) | M26: =IF(Calc!$A$25="","",Calc!V$25) | N26: =IF(Calc!$A$25="","",Calc!W$25) | O26: =IF(Calc!$A$25="","",Calc!X$25) | P26: =IF(Calc!$A$25="","",Calc!S$25) | Q26: =IF(Calc!$A$25="","",Calc!Y$25) | R26: =IF(Calc!$A$25="","",Calc!I$25) | S26: =IF(Calc!$A$25="","",Calc!Z$25) | T26: =IF(Calc!$A$25="","",Calc!AA$25) | U26: =IF(Calc!$A$25="","",Calc!AB$25) | V26: =IF(Calc!$A$25="","",Calc!AC$25) | W26: =IF(Calc!$A$25="","",Calc!AF$25) | X26: =IF(Calc!$A$25="","",Calc!AG$25) | Y26: =IF(Calc!$A$25="","",Calc!AH$25) | Z26: =IF(Calc!$A$25="","",Calc!AI$25) | AA26: =IF(Calc!$A$25="","",Calc!AJ$25) | AB26: =IF(Calc!$A$25="","",Calc!AK$25) | AC26: =IF(Calc!$A$25="","",Calc!AM$25)
A27: =IF(Calc!$A$26="","",Calc!A$26) | B27: =IF(Calc!$A$26="","",Calc!B$26) | C27: =IF(Calc!$A$26="","",Calc!C$26) | D27: =IF(Calc!$A$26="","",Calc!D$26) | E27: =IF(Calc!$A$26="","",Calc!J$26) | F27: =IF(Calc!$A$26="","",Calc!L$26) | G27: =IF(Calc!$A$26="","",Calc!N$26) | H27: =IF(Calc!$A$26="","",Calc!O$26) | I27: =IF(Calc!$A$26="","",Calc!Q$26) | J27: =IF(Calc!$A$26="","",Calc!R$26) | K27: =IF(Calc!$A$26="","",Calc!T$26) | L27: =IF(Calc!$A$26="","",Calc!U$26) | M27: =IF(Calc!$A$26="","",Calc!V$26) | N27: =IF(Calc!$A$26="","",Calc!W$26) | O27: =IF(Calc!$A$26="","",Calc!X$26) | P27: =IF(Calc!$A$26="","",Calc!S$26) | Q27: =IF(Calc!$A$26="","",Calc!Y$26) | R27: =IF(Calc!$A$26="","",Calc!I$26) | S27: =IF(Calc!$A$26="","",Calc!Z$26) | T27: =IF(Calc!$A$26="","",Calc!AA$26) | U27: =IF(Calc!$A$26="","",Calc!AB$26) | V27: =IF(Calc!$A$26="","",Calc!AC$26) | W27: =IF(Calc!$A$26="","",Calc!AF$26) | X27: =IF(Calc!$A$26="","",Calc!AG$26) | Y27: =IF(Calc!$A$26="","",Calc!AH$26) | Z27: =IF(Calc!$A$26="","",Calc!AI$26) | AA27: =IF(Calc!$A$26="","",Calc!AJ$26) | AB27: =IF(Calc!$A$26="","",Calc!AK$26) | AC27: =IF(Calc!$A$26="","",Calc!AM$26)
A29: 加速度(pp) ＝ 最新季 QoQ − 上一季 QoQ。QoQ ＝ 本季營收 ÷ 上一季營收 − 1（季度成長率）。正值代表這一季的成長速度比上一季快。
A30: ROE 顯示 N/M 代表股東權益為負（大量庫藏股或累積虧損），此時 ROE 沒有比較意義。殖利率顯示「不配息」代表該檔近四季沒有配息紀錄。
A31: 資料來源：yfinance / yahooquery / Alpha Vantage / SEC EDGAR

Sheet Stock_Card
A1: 個股卡 | Z1: =IF(INDEX(Calc!$AL$2:$AL$100,MATCH($B$2,Calc!$A$2:$A$100,0))<Config!$B$7,"⚠ 分析師家數不足，共識預估可信度低 ","")&IF(NOT(ISNUMBER(INDEX(Calc!$AF$2:$AF$100,MATCH($B$2,Calc!$A$2:$A$100,0)))),"⚠ 股東權益為負，ROE 無比較意義 ","")&IF(INDEX(Calc!$P$2:$P$100,MATCH($B$2,Calc!$A$2:$A$100,0))=0,"ℹ 此檔近四季未配息 ","")
A2: 選擇股票 → | B2: AAPL | D2: =IF($B$2="","",IFERROR(INDEX(Calc!$B$2:$B$100,MATCH($B$2,Calc!$A$2:$A$100,0)),"")) -> Apple Inc. | G2: =IF($B$2="","",IFERROR(INDEX(Calc!$C$2:$C$100,MATCH($B$2,Calc!$A$2:$A$100,0)),"")) -> 0
C3: ← 這個下拉同時驅動「年度檢視」與「季度檢視」兩頁
A4: 股價 | B4: =IF($B$2="","",IFERROR(INDEX(Calc!$D$2:$D$100,MATCH($B$2,Calc!$A$2:$A$100,0)),"")) -> 329.35999 | D4: 分析師家數 | E4: =IF($B$2="","",IFERROR(INDEX(Calc!$AL$2:$AL$100,MATCH($B$2,Calc!$A$2:$A$100,0)),"")) -> 27 | G4: 下次財報日 | H4: =IF($B$2="","",IFERROR(INDEX(Calc!$AM$2:$AM$100,MATCH($B$2,Calc!$A$2:$A$100,0)),"")) -> 46324 | I4: 資料日期 | J4: =IF($B$2="","",IFERROR(INDEX(Calc!$AN$2:$AN$100,MATCH($B$2,Calc!$A$2:$A$100,0)),"")) -> 46280
A6: 估值 · 殖利率 | D6: 成長 | G6: 毛利率 · ROE
A7: PE_TTM | B7: =IF($B$2="","",IFERROR(INDEX(Calc!$J$2:$J$100,MATCH($B$2,Calc!$A$2:$A$100,0)),"")) -> 37.770641 | D7: 營收QoQ 最新季 | E7: =IF($B$2="","",IFERROR(INDEX(Calc!$T$2:$T$100,MATCH($B$2,Calc!$A$2:$A$100,0)),"")) -> -0.015892574 | G7: 毛利率_TTM | H7: =IF($B$2="","",IFERROR(INDEX(Calc!$Z$2:$Z$100,MATCH($B$2,Calc!$A$2:$A$100,0)),"")) -> 0.48652916
A8: PE Forward | B8: =IF($B$2="","",IFERROR(INDEX(Calc!$L$2:$L$100,MATCH($B$2,Calc!$A$2:$A$100,0)),"")) -> 34.507766 | D8: 上一季 QoQ | E8: =IF($B$2="","",IFERROR(INDEX(Calc!$U$2:$U$100,MATCH($B$2,Calc!$A$2:$A$100,0)),"")) -> -0.22657837 | G8: 5 年平均 | H8: =IF($B$2="","",IFERROR(INDEX(Calc!$AA$2:$AA$100,MATCH($B$2,Calc!$A$2:$A$100,0)),"")) -> 0.45744556
A9: PEG_T | B9: =IF($B$2="","",IFERROR(INDEX(Calc!$N$2:$N$100,MATCH($B$2,Calc!$A$2:$A$100,0)),"")) -> 1.1685846 | D9: 加速度 (pp) | E9: =IF($B$2="","",IFERROR(INDEX(Calc!$V$2:$V$100,MATCH($B$2,Calc!$A$2:$A$100,0)),"")) -> 21.068579 | G9: 差距 (bps) | H9: =IF($B$2="","",IFERROR(INDEX(Calc!$AB$2:$AB$100,MATCH($B$2,Calc!$A$2:$A$100,0)),"")) -> 290.83593
A10: PEG_F | B10: =IF($B$2="","",IFERROR(INDEX(Calc!$O$2:$O$100,MATCH($B$2,Calc!$A$2:$A$100,0)),"")) -> 3.9973204 | D10: 動能判讀 | E10: =IF($B$2="","",IFERROR(INDEX(Calc!$W$2:$W$100,MATCH($B$2,Calc!$A$2:$A$100,0)),"")) -> 衰退但收斂 | G10: ΔGM_YoY (bps) | H10: =IF($B$2="","",IFERROR(INDEX(Calc!$AC$2:$AC$100,MATCH($B$2,Calc!$A$2:$A$100,0)),"")) -> 356.55013
A11: EPS_TTM (Adj) | B11: =IF($B$2="","",IFERROR(INDEX(Calc!$F$2:$F$100,MATCH($B$2,Calc!$A$2:$A$100,0)),"")) -> 8.72 | D11: 同期加速度 (pp) | E11: =IF($B$2="","",IFERROR(INDEX(Calc!$X$2:$X$100,MATCH($B$2,Calc!$A$2:$A$100,0)),"")) -> -0.20186874 | G11: ROE_TTM | H11: =IF($B$2="","",IFERROR(INDEX(Calc!$AF$2:$AF$100,MATCH($B$2,Calc!$A$2:$A$100,0)),"")) -> 1.486954
A12: EPS Forward | B12: =IF($B$2="","",IFERROR(INDEX(Calc!$H$2:$H$100,MATCH($B$2,Calc!$A$2:$A$100,0)),"")) -> 9.5445177 | D12: 營收YoY 最新季 | E12: =IF($B$2="","",IFERROR(INDEX(Calc!$S$2:$S$100,MATCH($B$2,Calc!$A$2:$A$100,0)),"")) -> 0.16356502 | G12: 5 年平均 | H12: =IF($B$2="","",IFERROR(INDEX(Calc!$AG$2:$AG$100,MATCH($B$2,Calc!$A$2:$A$100,0)),"")) -> 1.4327803
A13: 殖利率 | B13: =IF($B$2="","",IFERROR(INDEX(Calc!$Q$2:$Q$100,MATCH($B$2,Calc!$A$2:$A$100,0)),"")) -> 0.0031880011 | D13: EPS_YoY 最新季 | E13: =IF($B$2="","",IFERROR(INDEX(Calc!$Y$2:$Y$100,MATCH($B$2,Calc!$A$2:$A$100,0)),"")) -> 0.2866242 | G13: ROE Forward | H13: =IF($B$2="","",IFERROR(INDEX(Calc!$AH$2:$AH$100,MATCH($B$2,Calc!$A$2:$A$100,0)),"")) -> 1.2063557
A14: 每股配息 TTM | B14: =IF($B$2="","",IFERROR(INDEX(Calc!$P$2:$P$100,MATCH($B$2,Calc!$A$2:$A$100,0)),"")) -> 1.05 | D14: EPS成長_F (F1→F2) | E14: =IF($B$2="","",IFERROR(INDEX(Calc!$M$2:$M$100,MATCH($B$2,Calc!$A$2:$A$100,0)),"")) -> 0.086327246 | G14: 每股淨值 | H14: =IF($B$2="","",IFERROR(INDEX(Calc!$AD$2:$AD$100,MATCH($B$2,Calc!$A$2:$A$100,0)),"")) -> 7.3069907
D15: 當季EPS預估 | E15: =IF($B$2="","",IFERROR(INDEX(Calc!$AI$2:$AI$100,MATCH($B$2,Calc!$A$2:$A$100,0)),"")) -> 1.97656
A16: 旗標 | B16: =IF($B$2="","",IF(LEN($Z$1)=0,"✓ 目前沒有觸發任何旗標",$Z$1)) -> ✓ 目前沒有觸發任何旗標

Sheet 年度檢視
A1: 年度檢視 · 近六財年逐年指標 | Z1: =IF(Stock_Card!$B$2="","",IFERROR(SUMIFS(Raw_Q!$C$2:$C$600,Raw_Q!$A$2:$A$600,Stock_Card!$B$2,Raw_Q!$P$2:$P$600,0),"")) -> 2026
A2: 股票 | B2: =Stock_Card!$B$2 -> AAPL | C2: ← 在 Stock_Card 換股票，這一頁與「季度檢視」同步。每一列＝一個完整財年，全部由 Raw_Q 的季度資料 rollup 而來。
A4: 財年 | B4: 實際季數 | C4: 營收($M) | D4: 營收YoY | E4: 毛利率 | F4: 毛利率變化(bps) | G4: EPS(Adj) | H4: EPS YoY | I4: ROE | J4: 每股配息 | K4: 年末股價 | L4: 殖利率 | M4: PE | N4: PEG_T
A5: =IF(Stock_Card!$B$2="","",IFERROR($Z$1-5,"")) -> 2021 | B5: =IF(Stock_Card!$B$2="","",COUNTIFS(Raw_Q!$A$2:$A$600,Stock_Card!$B$2,Raw_Q!$C$2:$C$600,$A5,Raw_Q!$F$2:$F$600,"N")) -> 4 | C5: =IF($B5>=4,SUMIFS(Raw_Q!$I$2:$I$600,Raw_Q!$A$2:$A$600,Stock_Card!$B$2,Raw_Q!$C$2:$C$600,$A5,Raw_Q!$F$2:$F$600,"N"),"") -> 365817 | D5: =IFERROR(IF(AND(ISNUMBER(C5),ISNUMBER(C4)),C5/C4-1,""),"") | E5: =IF($B5>=4,IFERROR(SUMIFS(Raw_Q!$J$2:$J$600,Raw_Q!$A$2:$A$600,Stock_Card!$B$2,Raw_Q!$C$2:$C$600,$A5,Raw_Q!$F$2:$F$600,"N")/C5,""),"") -> 0.4177936 | F5: =IFERROR(IF(AND(ISNUMBER(E5),ISNUMBER(E4)),(E5-E4)*10000,""),"") | G5: =IF($B5>=4,SUMIFS(Raw_Q!$K$2:$K$600,Raw_Q!$A$2:$A$600,Stock_Card!$B$2,Raw_Q!$C$2:$C$600,$A5,Raw_Q!$F$2:$F$600,"N"),"") -> 5.62 | H5: =IFERROR(IF(AND(ISNUMBER(G5),ISNUMBER(G4)),G5/G4-1,""),"") | I5: =IF($B5>=4,IFERROR(IF(MIN(SUMIFS(Raw_Q!$M$2:$M$600,Raw_Q!$A$2:$A$600,Stock_Card!$B$2,Raw_Q!$C$2:$C$600,$A5,Raw_Q!$D$2:$D$600,4,Raw_Q!$F$2:$F$600,"N"),SUMIFS(Raw_Q!$M$2:$M$600,Raw_Q!$A$2:$A$600,Stock_Card!$B$2,Raw_Q!$C$2:$C$600,$A5-1,Raw_Q!$D$2:$D$600,4,Raw_Q!$F$2:$F$600,"N"))<=0,"N/M",SUMPRODUCT((Raw_Q!$A$2:$A$600=Stock_Card!$B$2)*(Raw_Q!$C$2:$C$600=$A5)*(Raw_Q!$F$2:$F$600="N")*Raw_Q!$K$2:$K$600*Raw_Q!$L$2:$L$600)/((SUMIFS(Raw_Q!$M$2:$M$600,Raw_Q!$A$2:$A$600,Stock_Card!$B$2,Raw_Q!$C$2:$C$600,$A5,Raw_Q!$D$2:$D$600,4,Raw_Q!$F$2:$F$600,"N")+SUMIFS(Raw_Q!$M$2:$M$600,Raw_Q!$A$2:$A$600,Stock_Card!$B$2,Raw_Q!$C$2:$C$600,$A5-1,Raw_Q!$D$2:$D$600,4,Raw_Q!$F$2:$F$600,"N"))/2)),"N/M"),"") -> 1.1565623 | J5: =IF($B5>=4,SUMIFS(Raw_Q!$N$2:$N$600,Raw_Q!$A$2:$A$600,Stock_Card!$B$2,Raw_Q!$C$2:$C$600,$A5,Raw_Q!$F$2:$F$600,"N"),"") -> 0.85 | K5: =IFERROR(IF(SUMIFS(Raw_Q!$O$2:$O$600,Raw_Q!$A$2:$A$600,Stock_Card!$B$2,Raw_Q!$C$2:$C$600,$A5,Raw_Q!$D$2:$D$600,4,Raw_Q!$F$2:$F$600,"N")=0,"",SUMIFS(Raw_Q!$O$2:$O$600,Raw_Q!$A$2:$A$600,Stock_Card!$B$2,Raw_Q!$C$2:$C$600,$A5,Raw_Q!$D$2:$D$600,4,Raw_Q!$F$2:$F$600,"N")),"") -> 141.5 | L5: =IFERROR(IF(OR(NOT(ISNUMBER(K5)),NOT(ISNUMBER(J5)),J5=0),"",J5/K5),"") -> 0.0060070671 | M5: =IFERROR(IF(OR(NOT(ISNUMBER(K5)),NOT(ISNUMBER(G5)),G5<=0),"",K5/G5),"") -> 25.177936 | N5: =IFERROR(IF(OR(NOT(ISNUMBER(M5)),NOT(ISNUMBER(H5))),"",IF(H5<Config!$B$6,"N/M",M5/(H5*100))),"")
A6: =IF(Stock_Card!$B$2="","",IFERROR($Z$1-4,"")) -> 2022 | B6: =IF(Stock_Card!$B$2="","",COUNTIFS(Raw_Q!$A$2:$A$600,Stock_Card!$B$2,Raw_Q!$C$2:$C$600,$A6,Raw_Q!$F$2:$F$600,"N")) -> 4 | C6: =IF($B6>=4,SUMIFS(Raw_Q!$I$2:$I$600,Raw_Q!$A$2:$A$600,Stock_Card!$B$2,Raw_Q!$C$2:$C$600,$A6,Raw_Q!$F$2:$F$600,"N"),"") -> 394328 | D6: =IFERROR(IF(AND(ISNUMBER(C6),ISNUMBER(C5)),C6/C5-1,""),"") -> 0.077937876 | E6: =IF($B6>=4,IFERROR(SUMIFS(Raw_Q!$J$2:$J$600,Raw_Q!$A$2:$A$600,Stock_Card!$B$2,Raw_Q!$C$2:$C$600,$A6,Raw_Q!$F$2:$F$600,"N")/C6,""),"") -> 0.43309631 | F6: =IFERROR(IF(AND(ISNUMBER(E6),ISNUMBER(E5)),(E6-E5)*10000,""),"") -> 153.02709 | G6: =IF($B6>=4,SUMIFS(Raw_Q!$K$2:$K$600,Raw_Q!$A$2:$A$600,Stock_Card!$B$2,Raw_Q!$C$2:$C$600,$A6,Raw_Q!$F$2:$F$600,"N"),"") -> 6.11 | H6: =IFERROR(IF(AND(ISNUMBER(G6),ISNUMBER(G5)),G6/G5-1,""),"") -> 0.087188612 | I6: =IF($B6>=4,IFERROR(IF(MIN(SUMIFS(Raw_Q!$M$2:$M$600,Raw_Q!$A$2:$A$600,Stock_Card!$B$2,Raw_Q!$C$2:$C$600,$A6,Raw_Q!$D$2:$D$600,4,Raw_Q!$F$2:$F$600,"N"),SUMIFS(Raw_Q!$M$2:$M$600,Raw_Q!$A$2:$A$600,Stock_Card!$B$2,Raw_Q!$C$2:$C$600,$A6-1,Raw_Q!$D$2:$D$600,4,Raw_Q!$F$2:$F$600,"N"))<=0,"N/M",SUMPRODUCT((Raw_Q!$A$2:$A$600=Stock_Card!$B$2)*(Raw_Q!$C$2:$C$600=$A6)*(Raw_Q!$F$2:$F$600="N")*Raw_Q!$K$2:$K$600*Raw_Q!$L$2:$L$600)/((SUMIFS(Raw_Q!$M$2:$M$600,Raw_Q!$A$2:$A$600,Stock_Card!$B$2,Raw_Q!$C$2:$C$600,$A6,Raw_Q!$D$2:$D$600,4,Raw_Q!$F$2:$F$600,"N")+SUMIFS(Raw_Q!$M$2:$M$600,Raw_Q!$A$2:$A$600,Stock_Card!$B$2,Raw_Q!$C$2:$C$600,$A6-1,Raw_Q!$D$2:$D$600,4,Raw_Q!$F$2:$F$600,"N"))/2)),"N/M"),"") -> 1.391294 | J6: =IF($B6>=4,SUMIFS(Raw_Q!$N$2:$N$600,Raw_Q!$A$2:$A$600,Stock_Card!$B$2,Raw_Q!$C$2:$C$600,$A6,Raw_Q!$F$2:$F$600,"N"),"") -> 0.9 | K6: =IFERROR(IF(SUMIFS(Raw_Q!$O$2:$O$600,Raw_Q!$A$2:$A$600,Stock_Card!$B$2,Raw_Q!$C$2:$C$600,$A6,Raw_Q!$D$2:$D$600,4,Raw_Q!$F$2:$F$600,"N")=0,"",SUMIFS(Raw_Q!$O$2:$O$600,Raw_Q!$A$2:$A$600,Stock_Card!$B$2,Raw_Q!$C$2:$C$600,$A6,Raw_Q!$D$2:$D$600,4,Raw_Q!$F$2:$F$600,"N")),"") -> 138.2 | L6: =IFERROR(IF(OR(NOT(ISNUMBER(K6)),NOT(ISNUMBER(J6)),J6=0),"",J6/K6),"") -> 0.0065123012 | M6: =IFERROR(IF(OR(NOT(ISNUMBER(K6)),NOT(ISNUMBER(G6)),G6<=0),"",K6/G6),"") -> 22.618657 | N6: =IFERROR(IF(OR(NOT(ISNUMBER(M6)),NOT(ISNUMBER(H6))),"",IF(H6<Config!$B$6,"N/M",M6/(H6*100))),"") -> 2.5942215
A7: =IF(Stock_Card!$B$2="","",IFERROR($Z$1-3,"")) -> 2023 | B7: =IF(Stock_Card!$B$2="","",COUNTIFS(Raw_Q!$A$2:$A$600,Stock_Card!$B$2,Raw_Q!$C$2:$C$600,$A7,Raw_Q!$F$2:$F$600,"N")) -> 4 | C7: =IF($B7>=4,SUMIFS(Raw_Q!$I$2:$I$600,Raw_Q!$A$2:$A$600,Stock_Card!$B$2,Raw_Q!$C$2:$C$600,$A7,Raw_Q!$F$2:$F$600,"N"),"") -> 383285 | D7: =IFERROR(IF(AND(ISNUMBER(C7),ISNUMBER(C6)),C7/C6-1,""),"") -> -0.028004605 | E7: =IF($B7>=4,IFERROR(SUMIFS(Raw_Q!$J$2:$J$600,Raw_Q!$A$2:$A$600,Stock_Card!$B$2,Raw_Q!$C$2:$C$600,$A7,Raw_Q!$F$2:$F$600,"N")/C7,""),"") -> 0.4413113 | F7: =IFERROR(IF(AND(ISNUMBER(E7),ISNUMBER(E6)),(E7-E6)*10000,""),"") -> 82.149902 | G7: =IF($B7>=4,SUMIFS(Raw_Q!$K$2:$K$600,Raw_Q!$A$2:$A$600,Stock_Card!$B$2,Raw_Q!$C$2:$C$600,$A7,Raw_Q!$F$2:$F$600,"N"),"") -> 6.12 | H7: =IFERROR(IF(AND(ISNUMBER(G7),ISNUMBER(G6)),G7/G6-1,""),"") -> 0.0016366612 | I7: =IF($B7>=4,IFERROR(IF(MIN(SUMIFS(Raw_Q!$M$2:$M$600,Raw_Q!$A$2:$A$600,Stock_Card!$B$2,Raw_Q!$C$2:$C$600,$A7,Raw_Q!$D$2:$D$600,4,Raw_Q!$F$2:$F$600,"N"),SUMIFS(Raw_Q!$M$2:$M$600,Raw_Q!$A$2:$A$600,Stock_Card!$B$2,Raw_Q!$C$2:$C$600,$A7-1,Raw_Q!$D$2:$D$600,4,Raw_Q!$F$2:$F$600,"N"))<=0,"N/M",SUMPRODUCT((Raw_Q!$A$2:$A$600=Stock_Card!$B$2)*(Raw_Q!$C$2:$C$600=$A7)*(Raw_Q!$F$2:$F$600="N")*Raw_Q!$K$2:$K$600*Raw_Q!$L$2:$L$600)/((SUMIFS(Raw_Q!$M$2:$M$600,Raw_Q!$A$2:$A$600,Stock_Card!$B$2,Raw_Q!$C$2:$C$600,$A7,Raw_Q!$D$2:$D$600,4,Raw_Q!$F$2:$F$600,"N")+SUMIFS(Raw_Q!$M$2:$M$600,Raw_Q!$A$2:$A$600,Stock_Card!$B$2,Raw_Q!$C$2:$C$600,$A7-1,Raw_Q!$D$2:$D$600,4,Raw_Q!$F$2:$F$600,"N"))/2)),"N/M"),"") -> 1.7204189 | J7: =IF($B7>=4,SUMIFS(Raw_Q!$N$2:$N$600,Raw_Q!$A$2:$A$600,Stock_Card!$B$2,Raw_Q!$C$2:$C$600,$A7,Raw_Q!$F$2:$F$600,"N"),"") -> 0.94 | K7: =IFERROR(IF(SUMIFS(Raw_Q!$O$2:$O$600,Raw_Q!$A$2:$A$600,Stock_Card!$B$2,Raw_Q!$C$2:$C$600,$A7,Raw_Q!$D$2:$D$600,4,Raw_Q!$F$2:$F$600,"N")=0,"",SUMIFS(Raw_Q!$O$2:$O$600,Raw_Q!$A$2:$A$600,Stock_Card!$B$2,Raw_Q!$C$2:$C$600,$A7,Raw_Q!$D$2:$D$600,4,Raw_Q!$F$2:$F$600,"N")),"") -> 171.21001 | L7: =IFERROR(IF(OR(NOT(ISNUMBER(K7)),NOT(ISNUMBER(J7)),J7=0),"",J7/K7),"") -> 0.0054903333 | M7: =IFERROR(IF(OR(NOT(ISNUMBER(K7)),NOT(ISNUMBER(G7)),G7<=0),"",K7/G7),"") -> 27.975491 | N7: =IFERROR(IF(OR(NOT(ISNUMBER(M7)),NOT(ISNUMBER(H7))),"",IF(H7<Config!$B$6,"N/M",M7/(H7*100))),"") -> N/M
A8: =IF(Stock_Card!$B$2="","",IFERROR($Z$1-2,"")) -> 2024 | B8: =IF(Stock_Card!$B$2="","",COUNTIFS(Raw_Q!$A$2:$A$600,Stock_Card!$B$2,Raw_Q!$C$2:$C$600,$A8,Raw_Q!$F$2:$F$600,"N")) -> 4 | C8: =IF($B8>=4,SUMIFS(Raw_Q!$I$2:$I$600,Raw_Q!$A$2:$A$600,Stock_Card!$B$2,Raw_Q!$C$2:$C$600,$A8,Raw_Q!$F$2:$F$600,"N"),"") -> 391035 | D8: =IFERROR(IF(AND(ISNUMBER(C8),ISNUMBER(C7)),C8/C7-1,""),"") -> 0.020219941 | E8: =IF($B8>=4,IFERROR(SUMIFS(Raw_Q!$J$2:$J$600,Raw_Q!$A$2:$A$600,Stock_Card!$B$2,Raw_Q!$C$2:$C$600,$A8,Raw_Q!$F$2:$F$600,"N")/C8,""),"") -> 0.4620635 | F8: =IFERROR(IF(AND(ISNUMBER(E8),ISNUMBER(E7)),(E8-E7)*10000,""),"") -> 207.52202 | G8: =IF($B8>=4,SUMIFS(Raw_Q!$K$2:$K$600,Raw_Q!$A$2:$A$600,Stock_Card!$B$2,Raw_Q!$C$2:$C$600,$A8,Raw_Q!$F$2:$F$600,"N"),"") -> 6.08 | H8: =IFERROR(IF(AND(ISNUMBER(G8),ISNUMBER(G7)),G8/G7-1,""),"") -> -0.0065359477 | I8: =IF($B8>=4,IFERROR(IF(MIN(SUMIFS(Raw_Q!$M$2:$M$600,Raw_Q!$A$2:$A$600,Stock_Card!$B$2,Raw_Q!$C$2:$C$600,$A8,Raw_Q!$D$2:$D$600,4,Raw_Q!$F$2:$F$600,"N"),SUMIFS(Raw_Q!$M$2:$M$600,Raw_Q!$A$2:$A$600,Stock_Card!$B$2,Raw_Q!$C$2:$C$600,$A8-1,Raw_Q!$D$2:$D$600,4,Raw_Q!$F$2:$F$600,"N"))<=0,"N/M",SUMPRODUCT((Raw_Q!$A$2:$A$600=Stock_Card!$B$2)*(Raw_Q!$C$2:$C$600=$A8)*(Raw_Q!$F$2:$F$600="N")*Raw_Q!$K$2:$K$600*Raw_Q!$L$2:$L$600)/((SUMIFS(Raw_Q!$M$2:$M$600,Raw_Q!$A$2:$A$600,Stock_Card!$B$2,Raw_Q!$C$2:$C$600,$A8,Raw_Q!$D$2:$D$600,4,Raw_Q!$F$2:$F$600,"N")+SUMIFS(Raw_Q!$M$2:$M$600,Raw_Q!$A$2:$A$600,Stock_Card!$B$2,Raw_Q!$C$2:$C$600,$A8-1,Raw_Q!$D$2:$D$600,4,Raw_Q!$F$2:$F$600,"N"))/2)),"N/M"),"") -> 1.5925679 | J8: =IF($B8>=4,SUMIFS(Raw_Q!$N$2:$N$600,Raw_Q!$A$2:$A$600,Stock_Card!$B$2,Raw_Q!$C$2:$C$600,$A8,Raw_Q!$F$2:$F$600,"N"),"") -> 0.98 | K8: =IFERROR(IF(SUMIFS(Raw_Q!$O$2:$O$600,Raw_Q!$A$2:$A$600,Stock_Card!$B$2,Raw_Q!$C$2:$C$600,$A8,Raw_Q!$D$2:$D$600,4,Raw_Q!$F$2:$F$600,"N")=0,"",SUMIFS(Raw_Q!$O$2:$O$600,Raw_Q!$A$2:$A$600,Stock_Card!$B$2,Raw_Q!$C$2:$C$600,$A8,Raw_Q!$D$2:$D$600,4,Raw_Q!$F$2:$F$600,"N")),"") -> 233 | L8: =IFERROR(IF(OR(NOT(ISNUMBER(K8)),NOT(ISNUMBER(J8)),J8=0),"",J8/K8),"") -> 0.0042060086 | M8: =IFERROR(IF(OR(NOT(ISNUMBER(K8)),NOT(ISNUMBER(G8)),G8<=0),"",K8/G8),"") -> 38.322368 | N8: =IFERROR(IF(OR(NOT(ISNUMBER(M8)),NOT(ISNUMBER(H8))),"",IF(H8<Config!$B$6,"N/M",M8/(H8*100))),"") -> N/M
A9: =IF(Stock_Card!$B$2="","",IFERROR($Z$1-1,"")) -> 2025 | B9: =IF(Stock_Card!$B$2="","",COUNTIFS(Raw_Q!$A$2:$A$600,Stock_Card!$B$2,Raw_Q!$C$2:$C$600,$A9,Raw_Q!$F$2:$F$600,"N")) -> 4 | C9: =IF($B9>=4,SUMIFS(Raw_Q!$I$2:$I$600,Raw_Q!$A$2:$A$600,Stock_Card!$B$2,Raw_Q!$C$2:$C$600,$A9,Raw_Q!$F$2:$F$600,"N"),"") -> 416161 | D9: =IFERROR(IF(AND(ISNUMBER(C9),ISNUMBER(C8)),C9/C8-1,""),"") -> 0.064255118 | E9: =IF($B9>=4,IFERROR(SUMIFS(Raw_Q!$J$2:$J$600,Raw_Q!$A$2:$A$600,Stock_Card!$B$2,Raw_Q!$C$2:$C$600,$A9,Raw_Q!$F$2:$F$600,"N")/C9,""),"") -> 0.46905164 | F9: =IFERROR(IF(AND(ISNUMBER(E9),ISNUMBER(E8)),(E9-E8)*10000,""),"") -> 69.881429 | G9: =IF($B9>=4,SUMIFS(Raw_Q!$K$2:$K$600,Raw_Q!$A$2:$A$600,Stock_Card!$B$2,Raw_Q!$C$2:$C$600,$A9,Raw_Q!$F$2:$F$600,"N"),"") -> 7.47 | H9: =IFERROR(IF(AND(ISNUMBER(G9),ISNUMBER(G8)),G9/G8-1,""),"") -> 0.22861842 | I9: =IF($B9>=4,IFERROR(IF(MIN(SUMIFS(Raw_Q!$M$2:$M$600,Raw_Q!$A$2:$A$600,Stock_Card!$B$2,Raw_Q!$C$2:$C$600,$A9,Raw_Q!$D$2:$D$600,4,Raw_Q!$F$2:$F$600,"N"),SUMIFS(Raw_Q!$M$2:$M$600,Raw_Q!$A$2:$A$600,Stock_Card!$B$2,Raw_Q!$C$2:$C$600,$A9-1,Raw_Q!$D$2:$D$600,4,Raw_Q!$F$2:$F$600,"N"))<=0,"N/M",SUMPRODUCT((Raw_Q!$A$2:$A$600=Stock_Card!$B$2)*(Raw_Q!$C$2:$C$600=$A9)*(Raw_Q!$F$2:$F$600="N")*Raw_Q!$K$2:$K$600*Raw_Q!$L$2:$L$600)/((SUMIFS(Raw_Q!$M$2:$M$600,Raw_Q!$A$2:$A$600,Stock_Card!$B$2,Raw_Q!$C$2:$C$600,$A9,Raw_Q!$D$2:$D$600,4,Raw_Q!$F$2:$F$600,"N")+SUMIFS(Raw_Q!$M$2:$M$600,Raw_Q!$A$2:$A$600,Stock_Card!$B$2,Raw_Q!$C$2:$C$600,$A9-1,Raw_Q!$D$2:$D$600,4,Raw_Q!$F$2:$F$600,"N"))/2)),"N/M"),"") -> 1.7258475 | J9: =IF($B9>=4,SUMIFS(Raw_Q!$N$2:$N$600,Raw_Q!$A$2:$A$600,Stock_Card!$B$2,Raw_Q!$C$2:$C$600,$A9,Raw_Q!$F$2:$F$600,"N"),"") -> 1.02 | K9: =IFERROR(IF(SUMIFS(Raw_Q!$O$2:$O$600,Raw_Q!$A$2:$A$600,Stock_Card!$B$2,Raw_Q!$C$2:$C$600,$A9,Raw_Q!$D$2:$D$600,4,Raw_Q!$F$2:$F$600,"N")=0,"",SUMIFS(Raw_Q!$O$2:$O$600,Raw_Q!$A$2:$A$600,Stock_Card!$B$2,Raw_Q!$C$2:$C$600,$A9,Raw_Q!$D$2:$D$600,4,Raw_Q!$F$2:$F$600,"N")),"") -> 254.63 | L9: =IFERROR(IF(OR(NOT(ISNUMBER(K9)),NOT(ISNUMBER(J9)),J9=0),"",J9/K9),"") -> 0.0040058123 | M9: =IFERROR(IF(OR(NOT(ISNUMBER(K9)),NOT(ISNUMBER(G9)),G9<=0),"",K9/G9),"") -> 34.087015 | N9: =IFERROR(IF(OR(NOT(ISNUMBER(M9)),NOT(ISNUMBER(H9))),"",IF(H9<Config!$B$6,"N/M",M9/(H9*100))),"") -> 1.4910004
A10: =IF(Stock_Card!$B$2="","",IFERROR($Z$1-0,"")) -> 2026 | B10: =IF(Stock_Card!$B$2="","",COUNTIFS(Raw_Q!$A$2:$A$600,Stock_Card!$B$2,Raw_Q!$C$2:$C$600,$A10,Raw_Q!$F$2:$F$600,"N")) -> 3 | C10: =IF($B10>=4,SUMIFS(Raw_Q!$I$2:$I$600,Raw_Q!$A$2:$A$600,Stock_Card!$B$2,Raw_Q!$C$2:$C$600,$A10,Raw_Q!$F$2:$F$600,"N"),"") | D10: =IFERROR(IF(AND(ISNUMBER(C10),ISNUMBER(C9)),C10/C9-1,""),"") | E10: =IF($B10>=4,IFERROR(SUMIFS(Raw_Q!$J$2:$J$600,Raw_Q!$A$2:$A$600,Stock_Card!$B$2,Raw_Q!$C$2:$C$600,$A10,Raw_Q!$F$2:$F$600,"N")/C10,""),"") | F10: =IFERROR(IF(AND(ISNUMBER(E10),ISNUMBER(E9)),(E10-E9)*10000,""),"") | G10: =IF($B10>=4,SUMIFS(Raw_Q!$K$2:$K$600,Raw_Q!$A$2:$A$600,Stock_Card!$B$2,Raw_Q!$C$2:$C$600,$A10,Raw_Q!$F$2:$F$600,"N"),"") | H10: =IFERROR(IF(AND(ISNUMBER(G10),ISNUMBER(G9)),G10/G9-1,""),"") | I10: =IF($B10>=4,IFERROR(IF(MIN(SUMIFS(Raw_Q!$M$2:$M$600,Raw_Q!$A$2:$A$600,Stock_Card!$B$2,Raw_Q!$C$2:$C$600,$A10,Raw_Q!$D$2:$D$600,4,Raw_Q!$F$2:$F$600,"N"),SUMIFS(Raw_Q!$M$2:$M$600,Raw_Q!$A$2:$A$600,Stock_Card!$B$2,Raw_Q!$C$2:$C$600,$A10-1,Raw_Q!$D$2:$D$600,4,Raw_Q!$F$2:$F$600,"N"))<=0,"N/M",SUMPRODUCT((Raw_Q!$A$2:$A$600=Stock_Card!$B$2)*(Raw_Q!$C$2:$C$600=$A10)*(Raw_Q!$F$2:$F$600="N")*Raw_Q!$K$2:$K$600*Raw_Q!$L$2:$L$600)/((SUMIFS(Raw_Q!$M$2:$M$600,Raw_Q!$A$2:$A$600,Stock_Card!$B$2,Raw_Q!$C$2:$C$600,$A10,Raw_Q!$D$2:$D$600,4,Raw_Q!$F$2:$F$600,"N")+SUMIFS(Raw_Q!$M$2:$M$600,Raw_Q!$A$2:$A$600,Stock_Card!$B$2,Raw_Q!$C$2:$C$600,$A10-1,Raw_Q!$D$2:$D$600,4,Raw_Q!$F$2:$F$600,"N"))/2)),"N/M"),"") | J10: =IF($B10>=4,SUMIFS(Raw_Q!$N$2:$N$600,Raw_Q!$A$2:$A$600,Stock_Card!$B$2,Raw_Q!$C$2:$C$600,$A10,Raw_Q!$F$2:$F$600,"N"),"") | K10: =IFERROR(IF(SUMIFS(Raw_Q!$O$2:$O$600,Raw_Q!$A$2:$A$600,Stock_Card!$B$2,Raw_Q!$C$2:$C$600,$A10,Raw_Q!$D$2:$D$600,4,Raw_Q!$F$2:$F$600,"N")=0,"",SUMIFS(Raw_Q!$O$2:$O$600,Raw_Q!$A$2:$A$600,Stock_Card!$B$2,Raw_Q!$C$2:$C$600,$A10,Raw_Q!$D$2:$D$600,4,Raw_Q!$F$2:$F$600,"N")),"") | L10: =IFERROR(IF(OR(NOT(ISNUMBER(K10)),NOT(ISNUMBER(J10)),J10=0),"",J10/K10),"") | M10: =IFERROR(IF(OR(NOT(ISNUMBER(K10)),NOT(ISNUMBER(G10)),G10<=0),"",K10/G10),"") | N10: =IFERROR(IF(OR(NOT(ISNUMBER(M10)),NOT(ISNUMBER(H10))),"",IF(H10<Config!$B$6,"N/M",M10/(H10*100))),"")
A11: ↓ 以下兩列是「現況」，不是年度值。F 欄在 TTM 列是「最新毛利率 − 5 年平均」。
A12: TTM / 最新季 | C12: =IF(Stock_Card!$B$2="","",IFERROR(INDEX(Calc!$E$2:$E$100,MATCH(Stock_Card!$B$2,Calc!$A$2:$A$100,0)),"")) -> 466823 | D12: =IF(Stock_Card!$B$2="","",IFERROR(INDEX(Calc!$S$2:$S$100,MATCH(Stock_Card!$B$2,Calc!$A$2:$A$100,0)),"")) -> 0.16356502 | E12: =IF(Stock_Card!$B$2="","",IFERROR(INDEX(Calc!$Z$2:$Z$100,MATCH(Stock_Card!$B$2,Calc!$A$2:$A$100,0)),"")) -> 0.48652916 | F12: =IF(Stock_Card!$B$2="","",IFERROR(INDEX(Calc!$AB$2:$AB$100,MATCH(Stock_Card!$B$2,Calc!$A$2:$A$100,0)),"")) -> 290.83593 | G12: =IF(Stock_Card!$B$2="","",IFERROR(INDEX(Calc!$F$2:$F$100,MATCH(Stock_Card!$B$2,Calc!$A$2:$A$100,0)),"")) -> 8.72 | H12: =IF(Stock_Card!$B$2="","",IFERROR(INDEX(Calc!$I$2:$I$100,MATCH(Stock_Card!$B$2,Calc!$A$2:$A$100,0)),"")) -> 0.323217 | I12: =IF(Stock_Card!$B$2="","",IFERROR(INDEX(Calc!$AF$2:$AF$100,MATCH(Stock_Card!$B$2,Calc!$A$2:$A$100,0)),"")) -> 1.486954 | J12: =IF(Stock_Card!$B$2="","",IFERROR(INDEX(Calc!$P$2:$P$100,MATCH(Stock_Card!$B$2,Calc!$A$2:$A$100,0)),"")) -> 1.05 | K12: =IF(Stock_Card!$B$2="","",IFERROR(INDEX(Calc!$D$2:$D$100,MATCH(Stock_Card!$B$2,Calc!$A$2:$A$100,0)),"")) -> 329.35999 | L12: =IF(Stock_Card!$B$2="","",IFERROR(INDEX(Calc!$Q$2:$Q$100,MATCH(Stock_Card!$B$2,Calc!$A$2:$A$100,0)),"")) -> 0.0031880011 | M12: =IF(Stock_Card!$B$2="","",IFERROR(INDEX(Calc!$J$2:$J$100,MATCH(Stock_Card!$B$2,Calc!$A$2:$A$100,0)),"")) -> 37.770641 | N12: =IF(Stock_Card!$B$2="","",IFERROR(INDEX(Calc!$N$2:$N$100,MATCH(Stock_Card!$B$2,Calc!$A$2:$A$100,0)),"")) -> 1.1685846
A13: Forward（分析師共識） | G13: =IF(Stock_Card!$B$2="","",IFERROR(INDEX(Calc!$H$2:$H$100,MATCH(Stock_Card!$B$2,Calc!$A$2:$A$100,0)),"")) -> 9.5445177 | H13: =IF(Stock_Card!$B$2="","",IFERROR(INDEX(Calc!$M$2:$M$100,MATCH(Stock_Card!$B$2,Calc!$A$2:$A$100,0)),"")) -> 0.086327246 | I13: =IF(Stock_Card!$B$2="","",IFERROR(INDEX(Calc!$AH$2:$AH$100,MATCH(Stock_Card!$B$2,Calc!$A$2:$A$100,0)),"")) -> 1.2063557 | M13: =IF(Stock_Card!$B$2="","",IFERROR(INDEX(Calc!$L$2:$L$100,MATCH(Stock_Card!$B$2,Calc!$A$2:$A$100,0)),"")) -> 34.507766 | N13: =IF(Stock_Card!$B$2="","",IFERROR(INDEX(Calc!$O$2:$O$100,MATCH(Stock_Card!$B$2,Calc!$A$2:$A$100,0)),"")) -> 3.9973204
A15: 近五年摘要
A16: 5 年平均毛利率 | C16: =IF(Stock_Card!$B$2="","",IFERROR(AVERAGE(E5:E9),"")) -> 0.44466327 | D16: 五個完整財年的算術平均
A17: 最新毛利率 − 5 年平均 (bps) | C17: =IF(Stock_Card!$B$2="","",IFERROR((E12-AVERAGE(E5:E9))*10000,"")) -> 418.65888 | D17: 正值＝目前毛利率高於五年常態
A18: 5 年平均 ROE | C18: =IF(Stock_Card!$B$2="","",IFERROR(AVERAGE(I5:I9),"")) -> 1.5173381 | D18: N/M 的年度會被自動略過
A19: 5 年平均殖利率 | C19: =IF(Stock_Card!$B$2="","",IFERROR(AVERAGE(L5:L9),"")) -> 0.0052443045 | D19: 以各財年年末股價計算
A22: PE 與殖利率都用「該財年年末股價」計算，不是用今天的股價除歷史數字——後者沒有估值意義。這需要 Raw_Q 的 price_at_end 欄。
A23: PEG_T ＝ 當年 PE ÷ 當年 EPS 成長率，是「市場當時為已實現成長付了多少」；PEG_F ＝ 前瞻 PE ÷ 預估成長率，才是估值指標。兩者不要混著解讀。
A24: 年度層刻意不放加速度——加速度是季度層的訊號（這一季有沒有比上一季快），放在年度層會遲鈍到失去意義。

Sheet 季度檢視
A1: 季度檢視 · 近 12 季 + 當季預估 | Z1: =IF(Stock_Card!$B$2="","",IFERROR(SUMIFS(Raw_Q!$C$2:$C$600,Raw_Q!$A$2:$A$600,Stock_Card!$B$2,Raw_Q!$P$2:$P$600,0),"")) -> 2026
A2: 股票 | B2: =Stock_Card!$B$2 -> AAPL | C2: ← 與 Stock_Card / 年度檢視 同步。每一列＝一個財季。加速度只做在這一層。
A4: 期別 | B4: 期末日 | C4: 營收($M) | D4: 營收QoQ | E4: 上一季QoQ | F4: 加速度(pp) | G4: 動能判讀 | H4: 同期加速度(pp) | I4: 營收YoY | J4: 毛利率 | K4: ΔGM_YoY(bps) | L4: EPS(Adj) | M4: EPS YoY | N4: 每股配息 | O4: 狀態
